Workbook

Sheet Cover Sheet
B2: Company Name
B3: Ticker
B4: Date

Sheet Summary
B2: Company Name
B3: Ticker
B4: Current Stock Price
B5: Weighted Implied Stock Price | C5: =(C9*D9)+(C10*D10) -> #VALUE!
B6: Implied Upside/Downside | C6: =(C4/C5-1) -> #VALUE!
B8: Method | C8: Weight | D8: Price Target
B9: DCF | C9: 0.5 | D9: =(C13*D13)+(C14*D14)+(C15*D15) -> #VALUE!
B10: Relative Valuation | C10: 0.5 | D10: =(C18*D18)+(C19*D19)+(C20*D20)+(C21*D21) -> #DIV/0!
B12: DCF Case | C12: Weight | D12: Price Target
B13: Base | C13: 0.6 | D13: ='DCF Base'!K48 -> #VALUE!
B14: Bear | C14: 0.2 | D14: ='DCF Bear'!K48 -> #VALUE!
B15: Bull | C15: 0.2 | D15: ='DCF Bull'!K48 -> #VALUE!
B17: Relative Method | C17: Weight | D17: Price Target
B18: EV/Sales | C18: =RV!J5 -> 0.25 | D18: =RV!D13 -> #DIV/0!
B19: Price/Sales | C19: =RV!J6 -> 0.25 | D19: =RV!E13 -> #DIV/0!
B20: Price/Earnings | C20: =RV!J7 -> 0.25 | D20: =RV!F13 -> #DIV/0!
B21: Price/Book Value | C21: =RV!J8 -> 0.25 | D21: =RV!G13 -> #DIV/0!

Sheet DCF Base
B2: "Company Name" DCF Analysis
B4: WACC | G4: Other Assumptions
B5: Beta | E5: A | G5: Fiscal Year End | J5: 46022
B6: Market Risk Premium | E6: A | G6: LTGR | J6: 0.02
B7: Risk Free Rate | E7: A | G7: Cash & Equivalents | J7: API
B8: Cost of Equity | E8: =E7+(E5*E6) -> #VALUE! | G8: Shares Outstanding | J8: API
B9: Weight of Equity | E9: =J10/SUM(J10:J11) -> #VALUE! | G9: Current Price | J9: API
B10: Cost of Debt | E10: # | G10: Mkt Cap | J10: API
B11: After Tax CoD | E11: =E10*(1-E13) -> #VALUE! | G11: BV Debt | J11: API Calc
B12: Weight of Debt | E12: =1-E9 -> #VALUE! | G12: Financial Units
B13: Tax Rate | E13: A
B14: WACC | E14: 0.08
B16: Free Cash Flow | D16: Year"A" | E16: Year"A" | F16: Year"A" | G16: Year"E" | H16: Year"E" | I16: Year"E" | J16: Year"E" | K16: Year"E"
B17: Revenue | D17: ='3 Statement'!D5 -> 0 | E17: ='3 Statement'!E5 -> 0 | F17: ='3 Statement'!F5 -> 0 | G17: ='3 Statement'!G5 -> 0 | H17: ='3 Statement'!H5 -> 0 | I17: ='3 Statement'!I5 -> 0 | J17: ='3 Statement'!J5 -> 0 | K17: ='3 Statement'!K5 -> 0
B18: Revenue Growth (%) | E18: =E17/D17-1 -> #DIV/0! | F18: =F17/E17-1 -> #DIV/0! | G18: =(1+'3 Statement'!O5) -> 1 | H18: =(1+'3 Statement'!P5) -> 1 | I18: =(1+'3 Statement'!Q5) -> 1 | J18: =(1+'3 Statement'!R5) -> 1 | K18: =(1+'3 Statement'!S5) -> 1
B19: (-) COGS | D19: ='3 Statement'!D6 -> 0 | E19: ='3 Statement'!E6 -> 0 | F19: ='3 Statement'!F6 -> 0 | G19: ='3 Statement'!G6 -> 0 | H19: ='3 Statement'!H6 -> 0 | I19: ='3 Statement'!I6 -> 0 | J19: ='3 Statement'!J6 -> 0 | K19: ='3 Statement'!K6 -> 0
B20: GP | D20: =D17-D19 -> 0 | E20: =E17-E19 -> 0 | F20: =F17-F19 -> 0 | G20: =G17-G19 -> 0 | H20: =H17-H19 -> 0 | I20: =I17-I19 -> 0 | J20: =J17-J19 -> 0 | K20: =K17-K19 -> 0
B21: GP Margin (%) | E21: =E20/D20-1 -> #DIV/0! | F21: =F20/E20-1 -> #DIV/0! | G21: ='3 Statement'!G8 -> 0 | H21: ='3 Statement'!H8 -> 0 | I21: ='3 Statement'!I8 -> 0 | J21: ='3 Statement'!J8 -> 0 | K21: ='3 Statement'!K8 -> 0
B23: (-) Op Ex | D23: =SUM('3 Statement'!D9:D11) -> 0 | E23: =SUM('3 Statement'!E9:E11) -> 0 | F23: =SUM('3 Statement'!F9:F11) -> 0 | G23: =SUM('3 Statement'!G9:G11) -> #DIV/0! | H23: =SUM('3 Statement'!H9:H11) -> #DIV/0! | I23: =SUM('3 Statement'!I9:I11) -> #DIV/0! | J23: =SUM('3 Statement'!J9:J11) -> #DIV/0! | K23: =SUM('3 Statement'!K9:K11) -> #DIV/0!
B24: EBIT | D24: =D20+D23 -> 0 | E24: =E20+E23 -> 0 | F24: =F20+F23 -> 0 | G24: ='3 Statement'!G12 -> 0 | H24: ='3 Statement'!H12 -> 0 | I24: ='3 Statement'!I12 -> 0 | J24: ='3 Statement'!J12 -> 0 | K24: ='3 Statement'!K12 -> 0
B25: EBIT Margin (%) | D25: =D24/D17 -> #DIV/0! | E25: =E24/E17 -> #DIV/0! | F25: =F24/F17 -> #DIV/0! | G25: ='3 Statement'!G13 -> 0 | H25: ='3 Statement'!H13 -> 0 | I25: ='3 Statement'!I13 -> 0 | J25: ='3 Statement'!J13 -> 0 | K25: ='3 Statement'!K13 -> 0
B27: NOPAT | D27: =D24*(1-$E$13) -> #VALUE! | E27: =E24*(1-$E$13) -> #VALUE! | F27: =F24*(1-$E$13) -> #VALUE! | G27: =G24*(1-$E$13) -> #VALUE! | H27: =H24*(1-$E$13) -> #VALUE! | I27: =I24*(1-$E$13) -> #VALUE! | J27: =J24*(1-$E$13) -> #VALUE! | K27: =K24*(1-$E$13) -> #VALUE!
B28: (+) D&A | D28: ='3 Statement'!D73 -> 0 | E28: ='3 Statement'!E73 -> 0 | F28: ='3 Statement'!F73 -> 0 | G28: ='3 Statement'!G73 -> #DIV/0! | H28: ='3 Statement'!H73 -> #DIV/0! | I28: ='3 Statement'!I73 -> #DIV/0! | J28: ='3 Statement'!J73 -> #DIV/0! | K28: ='3 Statement'!K73 -> #DIV/0!
B29: (-) CapEx | D29: ='3 Statement'!D84 -> 0 | E29: ='3 Statement'!E84 -> 0 | F29: ='3 Statement'!F84 -> 0 | G29: ='3 Statement'!G84 -> 0 | H29: ='3 Statement'!H84 -> 0 | I29: ='3 Statement'!I84 -> 0 | J29: ='3 Statement'!J84 -> 0 | K29: ='3 Statement'!K84 -> 0
B30: (-) Changes in WC | D30: ='3 Statement'!D76 -> 0 | E30: ='3 Statement'!E76 -> 0 | F30: ='3 Statement'!F76 -> 0 | G30: ='3 Statement'!G76 -> #DIV/0! | H30: ='3 Statement'!H76 -> #DIV/0! | I30: ='3 Statement'!I76 -> #DIV/0! | J30: ='3 Statement'!J76 -> #DIV/0! | K30: ='3 Statement'!K76 -> #DIV/0!
B31: Unlevered Free Cash Flow | D31: =D27+D28+D29+D30 -> #VALUE! | E31: =E27+E28+E29+E30 -> #VALUE! | F31: =F27+F28+F29+F30 -> #VALUE! | G31: =G27+G28+G29+G30 -> #VALUE! | H31: =H27+H28+H29+H30 -> #VALUE! | I31: =I27+I28+I29+I30 -> #VALUE! | J31: =J27+J28+J29+J30 -> #VALUE! | K31: =K27+K28+K29+K30 -> #VALUE!
B33: DCF | G33: Year"E" | H33: Year"E" | I33: Year"E" | J33: Year"E" | K33: Year"E"
B34: Discount Period | G34: =YEARFRAC(TODAY(),$J$5) -> 0.077777778 | H34: =G34+1 -> 1.0777778 | I34: =H34+1 -> 2.0777778 | J34: =I34+1 -> 3.0777778 | K34: =J34+1 -> 4.0777778
B35: Discount Factor | G35: =(1/(1+$E$14))^G34 -> 0.99403202 | H35: =(1/(1+$E$14))^H34 -> 0.92040002 | I35: =(1/(1+$E$14))^I34 -> 0.85222224 | J35: =(1/(1+$E$14))^J34 -> 0.78909467 | K35: =(1/(1+$E$14))^K34 -> 0.73064321
B37: PV of UFCF | G37: =G31*G35 -> #VALUE! | H37: =H31*H35 -> #VALUE! | I37: =I31*I35 -> #VALUE! | J37: =J31*J35 -> #VALUE! | K37: =K31*K35 -> #VALUE!
B38: Total PV of UFCF | K38: =SUM(G37:K37) -> #VALUE!
B40: Terminal Value | K40: =(K31*(1+J6))/(E14-J6) -> #VALUE!
B41: PV of TV | K41: =K40*K35 -> #VALUE!
B43: Enterprise Value | K43: =K41+K38 -> #VALUE!
B44: (-) Net Debt | K44: =J11-J7 -> #VALUE!
B45: Equity Value | K45: =K41-K44 -> #VALUE!
B47: (/) Shares Outstanding | K47: =J8 -> API
B48: Per Share Price Target | K48: =K45/K47 -> #VALUE!
B49: Implied Upside/Downside | K49: =(K48/J9-1)*100 -> #VALUE!
B51: Sensitivity Analysis
...

Sheet DCF Bear
B2: "Company Name" DCF Analysis
B4: WACC | G4: Other Assumptions
B5: Beta | E5: # | G5: Fiscal Year End | J5: 46022
B6: Market Risk Premium | E6: # | G6: LTGR | J6: 0.02
B7: Risk Free Rate | E7: # | G7: Cash & Equivalents | J7: #
B8: Cost of Equity | E8: =E7+(E5*E6) -> #VALUE! | G8: Diluted S/O | J8: #
B9: Weight of Equity | E9: =J10/SUM(J10:J11) -> #VALUE! | G9: Current Price | J9: #
B10: Cost of Debt | E10: # | G10: Mkt Cap | J10: =J8*J9 -> #VALUE!
B11: After Tax CoD | E11: =E10*(1-E13) -> #VALUE! | G11: BV Debt
B12: Weight of Debt | E12: =1-E9 -> #VALUE! | G12: Financial Units
B13: Tax Rate | E13: #
B14: WACC | E14: 0.08
B16: Free Cash Flow | D16: Year"A" | E16: Year"A" | F16: Year"A" | G16: Year"E" | H16: Year"E" | I16: Year"E" | J16: Year"E" | K16: Year"E"
B17: Revenue | D17: ='3 Statement'!D5 -> 0 | E17: ='3 Statement'!E5 -> 0 | F17: ='3 Statement'!F5 -> 0 | G17: =F17*G18 -> 0 | H17: =G17*H18 -> 0 | I17: =H17*I18 -> 0 | J17: =I17*J18 -> 0 | K17: =J17*K18 -> 0
B18: Revenue Growth (%) | E18: =E17/D17-1 -> #DIV/0! | F18: =F17/E17-1 -> #DIV/0! | G18: =(1+O17) -> 1 | H18: =(1+P17) -> 1 | I18: =(1+Q17) -> 1 | J18: =(1+R17) -> 1 | K18: =(1+S17) -> 1
B19: (-) COGS | D19: ='3 Statement'!D6 -> 0 | E19: ='3 Statement'!E6 -> 0 | F19: ='3 Statement'!F6 -> 0 | G19: =G17*G21 -> #VALUE! | H19: =H17*H21 -> #VALUE! | I19: =I17*I21 -> #VALUE! | J19: =J17*J21 -> #VALUE! | K19: =K17*K21 -> #VALUE!
B20: GP | D20: =D17-D19 -> 0 | E20: =E17-E19 -> 0 | F20: =F17-F19 -> 0 | G20: =G17-G19 -> #VALUE! | H20: =H17-H19 -> #VALUE! | I20: =I17-I19 -> #VALUE! | J20: =J17-J19 -> #VALUE! | K20: =K17-K19 -> #VALUE!
B21: GP Margin (%) | E21: =E20/D20-1 -> #DIV/0! | F21: =F20/E20-1 -> #DIV/0! | G21: ASSUMPTION | H21: ASSUMPTION | I21: ASSUMPTION | J21: ASSUMPTION | K21: ASSUMPTION
B23: (-) Op Ex | D23: =SUM('3 Statement'!D9:D11) -> 0 | E23: =SUM('3 Statement'!E9:E11) -> 0 | F23: =SUM('3 Statement'!F9:F11) -> 0 | G23: =G17*G25 -> #VALUE! | H23: =H17*H25 -> #VALUE! | I23: =I17*I25 -> #VALUE! | J23: =J17*J25 -> #VALUE! | K23: =K17*K25 -> #VALUE!
B24: EBIT | D24: =D20+D23 -> 0 | E24: =E20+E23 -> 0 | F24: =F20+F23 -> 0 | G24: =G21-G23 -> #VALUE! | H24: =H21-H23 -> #VALUE! | I24: =I21-I23 -> #VALUE! | J24: =J21-J23 -> #VALUE! | K24: =K21-K23 -> #VALUE!
B25: EBIT Margin (%) | D25: =D24/D17 -> #DIV/0! | E25: =E24/E17 -> #DIV/0! | F25: =F24/F17 -> #DIV/0! | G25: ASSUMPTION | H25: ASSUMPTION | I25: ASSUMPTION | J25: ASSUMPTION | K25: ASSUMPTION
B27: NOPAT | D27: =D24*(1-$E$13) -> #VALUE! | E27: =E24*(1-$E$13) -> #VALUE! | F27: =F24*(1-$E$13) -> #VALUE! | G27: =G24*(1-$E$13) -> #VALUE! | H27: =H24*(1-$E$13) -> #VALUE! | I27: =I24*(1-$E$13) -> #VALUE! | J27: =J24*(1-$E$13) -> #VALUE! | K27: =K24*(1-$E$13) -> #VALUE!
B28: (+) D&A | D28: ='3 Statement'!D73 -> 0 | E28: ='3 Statement'!E73 -> 0 | F28: ='3 Statement'!F73 -> 0 | G28: ASSUMPTION | H28: ASSUMPTION | I28: ASSUMPTION | J28: ASSUMPTION | K28: ASSUMPTION
B29: (-) CapEx | D29: ='3 Statement'!D84 -> 0 | E29: ='3 Statement'!E84 -> 0 | F29: ='3 Statement'!F84 -> 0 | G29: ASSUMPTION | H29: ASSUMPTION | I29: ASSUMPTION | J29: ASSUMPTION | K29: ASSUMPTION
B30: (-) Changes in WC | D30: ='3 Statement'!D76 -> 0 | E30: ='3 Statement'!E76 -> 0 | F30: ='3 Statement'!F76 -> 0 | G30: ASSUMPTION | H30: ASSUMPTION | I30: ASSUMPTION | J30: ASSUMPTION | K30: ASSUMPTION
B31: Unlevered Free Cash Flow | D31: =D27+D28+D29+D30 -> #VALUE! | E31: =E27+E28+E29+E30 -> #VALUE! | F31: =F27+F28+F29+F30 -> #VALUE! | G31: =G27+G28+G29+G30 -> #VALUE! | H31: =H27+H28+H29+H30 -> #VALUE! | I31: =I27+I28+I29+I30 -> #VALUE! | J31: =J27+J28+J29+J30 -> #VALUE! | K31: =K27+K28+K29+K30 -> #VALUE!
B33: DCF | G33: Year"E" | H33: Year"E" | I33: Year"E" | J33: Year"E" | K33: Year"E"
B34: Discount Period | G34: =YEARFRAC(TODAY(),$J$5) -> 0.077777778 | H34: =G34+1 -> 1.0777778 | I34: =H34+1 -> 2.0777778 | J34: =I34+1 -> 3.0777778 | K34: =J34+1 -> 4.0777778
B35: Discount Factor | G35: =(1/(1+$E$14))^G34 -> 0.99403202 | H35: =(1/(1+$E$14))^H34 -> 0.92040002 | I35: =(1/(1+$E$14))^I34 -> 0.85222224 | J35: =(1/(1+$E$14))^J34 -> 0.78909467 | K35: =(1/(1+$E$14))^K34 -> 0.73064321
B37: PV of UFCF | G37: =G31*G35 -> #VALUE! | H37: =H31*H35 -> #VALUE! | I37: =I31*I35 -> #VALUE! | J37: =J31*J35 -> #VALUE! | K37: =K31*K35 -> #VALUE!
B38: Total PV of UFCF | K38: =SUM(G37:K37) -> #VALUE!
B40: Terminal Value | K40: =(K31*(1+J6))/(E14-J6) -> #VALUE!
B41: PV of TV | K41: =K40*K35 -> #VALUE!
B43: Enterprise Value | K43: =K41+K38 -> #VALUE!
B44: (-) Net Debt | K44: =J11-J7 -> #VALUE!
B45: Equity Value | K45: =K41-K44 -> #VALUE!
B47: (/) Shares Outstanding | K47: =J8 -> #
B48: Per Share Price Target | K48: =K45/K47 -> #VALUE!
B49: Implied Upside/Downside | K49: =(K48/J9-1)*100 -> #VALUE!
B51: Sensitivity Analysis
...

Sheet DCF Bull
B2: "Company Name" DCF Analysis
B4: WACC | G4: Other Assumptions
B5: Beta | E5: # | G5: Fiscal Year End | J5: 46022
B6: Market Risk Premium | E6: # | G6: LTGR | J6: 0.02
B7: Risk Free Rate | E7: # | G7: Cash & Equivalents | J7: #
B8: Cost of Equity | E8: =E7+(E5*E6) -> #VALUE! | G8: Diluted S/O | J8: #
B9: Weight of Equity | E9: =J10/SUM(J10:J11) -> #VALUE! | G9: Current Price | J9: #
B10: Cost of Debt | E10: # | G10: Mkt Cap | J10: =J8*J9 -> #VALUE!
B11: After Tax CoD | E11: =E10*(1-E13) -> #VALUE! | G11: BV Debt
B12: Weight of Debt | E12: =1-E9 -> #VALUE! | G12: Financial Units
B13: Tax Rate | E13: #
B14: WACC | E14: 0.08
B16: Free Cash Flow | D16: Year"A" | E16: Year"A" | F16: Year"A" | G16: Year"E" | H16: Year"E" | I16: Year"E" | J16: Year"E" | K16: Year"E"
B17: Revenue | D17: ='3 Statement'!D5 -> 0 | E17: ='3 Statement'!E5 -> 0 | F17: ='3 Statement'!F5 -> 0 | G17: =F17*G18 -> #VALUE! | H17: =G17*H18 -> #VALUE! | I17: =H17*I18 -> #VALUE! | J17: =I17*J18 -> #VALUE! | K17: =J17*K18 -> #VALUE!
B18: Revenue Growth (%) | E18: =E17/D17-1 -> #DIV/0! | F18: =F17/E17-1 -> #DIV/0! | G18: ASSUMPTION | H18: ASSUMPTION | I18: ASSUMPTION | J18: ASSUMPTION | K18: ASSUMPTION
B19: (-) COGS | D19: ='3 Statement'!D6 -> 0 | E19: ='3 Statement'!E6 -> 0 | F19: ='3 Statement'!F6 -> 0 | G19: =G17*G21 -> #VALUE! | H19: =H17*H21 -> #VALUE! | I19: =I17*I21 -> #VALUE! | J19: =J17*J21 -> #VALUE! | K19: =K17*K21 -> #VALUE!
B20: GP | D20: =D17-D19 -> 0 | E20: =E17-E19 -> 0 | F20: =F17-F19 -> 0 | G20: =G17-G19 -> #VALUE! | H20: =H17-H19 -> #VALUE! | I20: =I17-I19 -> #VALUE! | J20: =J17-J19 -> #VALUE! | K20: =K17-K19 -> #VALUE!
B21: GP Margin (%) | E21: =E20/D20-1 -> #DIV/0! | F21: =F20/E20-1 -> #DIV/0! | G21: ASSUMPTION | H21: ASSUMPTION | I21: ASSUMPTION | J21: ASSUMPTION | K21: ASSUMPTION
B23: (-) Op Ex | D23: =SUM('3 Statement'!D9:D11) -> 0 | E23: =SUM('3 Statement'!E9:E11) -> 0 | F23: =SUM('3 Statement'!F9:F11) -> 0 | G23: =G17*G25 -> #VALUE! | H23: =H17*H25 -> #VALUE! | I23: =I17*I25 -> #VALUE! | J23: =J17*J25 -> #VALUE! | K23: =K17*K25 -> #VALUE!
B24: EBIT | D24: =D20+D23 -> 0 | E24: =E20+E23 -> 0 | F24: =F20+F23 -> 0 | G24: =G21-G23 -> #VALUE! | H24: =H21-H23 -> #VALUE! | I24: =I21-I23 -> #VALUE! | J24: =J21-J23 -> #VALUE! | K24: =K21-K23 -> #VALUE!
B25: EBIT Margin (%) | D25: =D24/D17 -> #DIV/0! | E25: =E24/E17 -> #DIV/0! | F25: =F24/F17 -> #DIV/0! | G25: ASSUMPTION | H25: ASSUMPTION | I25: ASSUMPTION | J25: ASSUMPTION | K25: ASSUMPTION
B27: NOPAT | D27: =D24*(1-$E$13) -> #VALUE! | E27: =E24*(1-$E$13) -> #VALUE! | F27: =F24*(1-$E$13) -> #VALUE! | G27: =G24*(1-$E$13) -> #VALUE! | H27: =H24*(1-$E$13) -> #VALUE! | I27: =I24*(1-$E$13) -> #VALUE! | J27: =J24*(1-$E$13) -> #VALUE! | K27: =K24*(1-$E$13) -> #VALUE!
B28: (+) D&A | D28: ='3 Statement'!D73 -> 0 | E28: ='3 Statement'!E73 -> 0 | F28: ='3 Statement'!F73 -> 0 | G28: ASSUMPTION | H28: ASSUMPTION | I28: ASSUMPTION | J28: ASSUMPTION | K28: ASSUMPTION
B29: (-) CapEx | D29: ='3 Statement'!D84 -> 0 | E29: ='3 Statement'!E84 -> 0 | F29: ='3 Statement'!F84 -> 0 | G29: ASSUMPTION | H29: ASSUMPTION | I29: ASSUMPTION | J29: ASSUMPTION | K29: ASSUMPTION
B30: (-) Changes in WC | D30: ='3 Statement'!D76 -> 0 | E30: ='3 Statement'!E76 -> 0 | F30: ='3 Statement'!F76 -> 0 | G30: ASSUMPTION | H30: ASSUMPTION | I30: ASSUMPTION | J30: ASSUMPTION | K30: ASSUMPTION
B31: Unlevered Free Cash Flow | D31: =D27+D28+D29+D30 -> #VALUE! | E31: =E27+E28+E29+E30 -> #VALUE! | F31: =F27+F28+F29+F30 -> #VALUE! | G31: =G27+G28+G29+G30 -> #VALUE! | H31: =H27+H28+H29+H30 -> #VALUE! | I31: =I27+I28+I29+I30 -> #VALUE! | J31: =J27+J28+J29+J30 -> #VALUE! | K31: =K27+K28+K29+K30 -> #VALUE!
B33: DCF | G33: Year"E" | H33: Year"E" | I33: Year"E" | J33: Year"E" | K33: Year"E"
B34: Discount Period | G34: =YEARFRAC(TODAY(),$J$5) -> 0.077777778 | H34: =G34+1 -> 1.0777778 | I34: =H34+1 -> 2.0777778 | J34: =I34+1 -> 3.0777778 | K34: =J34+1 -> 4.0777778
B35: Discount Factor | G35: =(1/(1+$E$14))^G34 -> 0.99403202 | H35: =(1/(1+$E$14))^H34 -> 0.92040002 | I35: =(1/(1+$E$14))^I34 -> 0.85222224 | J35: =(1/(1+$E$14))^J34 -> 0.78909467 | K35: =(1/(1+$E$14))^K34 -> 0.73064321
B37: PV of UFCF | G37: =G31*G35 -> #VALUE! | H37: =H31*H35 -> #VALUE! | I37: =I31*I35 -> #VALUE! | J37: =J31*J35 -> #VALUE! | K37: =K31*K35 -> #VALUE!
B38: Total PV of UFCF | K38: =SUM(G37:K37) -> #VALUE!
B40: Terminal Value | K40: =(K31*(1+J6))/(E14-J6) -> #VALUE!
B41: PV of TV | K41: =K40*K35 -> #VALUE!
B43: Enterprise Value | K43: =K41+K38 -> #VALUE!
B44: (-) Net Debt | K44: =J11-J7 -> #VALUE!
B45: Equity Value | K45: =K41-K44 -> #VALUE!
B47: (/) Shares Outstanding | K47: =J8 -> #
B48: Per Share Price Target | K48: =K45/K47 -> #VALUE!
B49: Implied Upside/Downside | K49: =(K48/J9-1)*100 -> #VALUE!
B51: Sensitivity Analysis
...

Sheet 3 Statement
B2: "Company Name" 3 Statement Model (UNITS)
B4: Income Statement | D4: Year"A" | E4: Year"A" | F4: Year"A" | G4: Year"E" | H4: Year"E" | I4: Year"E" | J4: Year"E" | K4: Year"E" | M4: Assumptions | N4: Type | O4: Value
B5: Revenue | G5: =F5*(1+O5) -> 0 | H5: =G5*(1+P5) -> 0 | I5: =H5*(1+Q5) -> 0 | J5: =I5*(1+R5) -> 0 | K5: =J5*(1+S5) -> 0 | M5: Revenue | V5: 416161000000
B6: Cost of Revenue | G6: =G5-G7 -> 0 | H6: =H5-H7 -> 0 | I6: =I5-I7 -> 0 | J6: =J5-J7 -> 0 | K6: =K5-K7 -> 0 | M6: Gross Margin | V6: 220960000000 | Y6: "researchAndDevelopmentExpenses": 34550000000,
B7: Gross Profit | G7: =G8*G5 -> 0 | H7: =H8*H5 -> 0 | I7: =I8*I5 -> 0 | J7: =J8*J5 -> 0 | K7: =K8*K5 -> 0 | M7: Operating Margin | V7: 195201000000 | Y7: "generalAndAdministrativeExpenses": 0,
B8: Gross Margin % | G8: =F8+(O6) -> 0 | H8: =G8+(P6) -> 0 | I8: =H8+(Q6) -> 0 | J8: =I8+(R6) -> 0 | K8: =J8+(S6) -> 0 | M8: EBITDA Margin | V8: 34550000000 | Y8: "sellingAndMarketingExpenses": 0,
B9: Research & Development Expenses | G9: =(F9/F12)*(G7-G12) -> #DIV/0! | H9: =(G9/G12)*(H7-H12) -> #DIV/0! | I9: =(H9/H12)*(I7-I12) -> #DIV/0! | J9: =(I9/I12)*(J7-J12) -> #DIV/0! | K9: =(J9/J12)*(K7-K12) -> #DIV/0! | M9: Tax Rate | V9: 0 | Y9: "sellingGeneralAndAdministrativeExpenses": 27601000000,
B10: Selling, General & Administrative Expenses (SG&A) | G10: =(F10/F12)*(G7-G12) -> #DIV/0! | H10: =(G10/G12)*(H7-H12) -> #DIV/0! | I10: =(H10/H12)*(I7-I12) -> #DIV/0! | J10: =(I10/I12)*(J7-J12) -> #DIV/0! | K10: =(J10/J12)*(K7-K12) -> #DIV/0! | M10: Interest Rate on Debt | V10: 0 | Y10: "otherExpenses": 0,
B11: Other Expenses | G11: =(F11/F12)*(G7-G12) -> #DIV/0! | H11: =(G11/G12)*(H7-H12) -> #DIV/0! | I11: =(H11/H12)*(I7-I12) -> #DIV/0! | J11: =(I11/I12)*(J7-J12) -> #DIV/0! | K11: =(J11/J12)*(K7-K12) -> #DIV/0! | V11: 27601000000 | Y11: "operatingExpenses": 62151000000,
B12: Operating Profit | G12: =G13*G5 -> 0 | H12: =H13*H5 -> 0 | I12: =I13*I5 -> 0 | J12: =J13*J5 -> 0 | K12: =K13*K5 -> 0
B13: Operating Margin % | G13: =F13+O7 -> 0 | H13: =G13+P7 -> 0 | I13: =H13+Q7 -> 0 | J13: =I13+R7 -> 0 | K13: =J13+S7 -> 0
B14: Net Interest Income | G14: =($F$14/$F$5)*G5 -> #DIV/0! | H14: =($F$14/$F$5)*H5 -> #DIV/0! | I14: =($F$14/$F$5)*I5 -> #DIV/0! | J14: =($F$14/$F$5)*J5 -> #DIV/0! | K14: =($F$14/$F$5)*K5 -> #DIV/0!
B15: Other Non Operating Expenses | G15: =($F$15/$F$5)*G5 -> #DIV/0! | H15: =($F$15/$F$5)*H5 -> #DIV/0! | I15: =($F$15/$F$5)*I5 -> #DIV/0! | J15: =($F$15/$F$5)*J5 -> #DIV/0! | K15: =($F$15/$F$5)*K5 -> #DIV/0!
B16: Income Before Taxes | G16: =G12-G14-G15 -> #DIV/0! | H16: =H12-H14-H15 -> #DIV/0! | I16: =I12-I14-I15 -> #DIV/0! | J16: =J12-J14-J15 -> #DIV/0! | K16: =K12-K14-K15 -> #DIV/0!
B17: Income Tax Expense | G17: =G16*O9 -> #DIV/0! | H17: =H16*P9 -> #DIV/0! | I17: =I16*Q9 -> #DIV/0! | J17: =J16*R9 -> #DIV/0! | K17: =K16*S9 -> #DIV/0!
B18: Net Income | G18: =G16-G17 -> #DIV/0! | H18: =H16-H17 -> #DIV/0! | I18: =I16-I17 -> #DIV/0! | J18: =J16-J17 -> #DIV/0! | K18: =K16-K17 -> #DIV/0!
B19: Net Income Margin % | G19: =G18/G5 -> #DIV/0! | H19: =H18/H5 -> #DIV/0! | I19: =I18/I5 -> #DIV/0! | J19: =J18/J5 -> #DIV/0! | K19: =K18/K5 -> #DIV/0!
B20: EPS | G20: =G18/G21 -> #DIV/0! | H20: =H18/H21 -> #DIV/0! | I20: =I18/I21 -> #DIV/0! | J20: =J18/J21 -> #DIV/0! | K20: =K18/K21 -> #DIV/0!
B21: Weighted Average Shares Outstanding | G21: =F21+O72 -> 0 | H21: =G21+P72 -> 0 | I21: =H21+Q72 -> 0 | J21: =I21+R72 -> 0 | K21: =J21+S72 -> 0
B24: Balance Sheet | D24: Year"A" | E24: Year"A" | F24: Year"A" | G24: Year"E" | H24: Year"E" | I24: Year"E" | J24: Year"E" | K24: Year"E" | M24: Assumptions | N24: Type | O24: Value
B25: Cash & Cash Equivalents | G25: =G114 -> 0 | H25: =H114 -> 0 | I25: =I114 -> 0 | J25: =J114 -> 0 | K25: =K114 -> 0 | M25: Depreciation % of PPE
B26: Short-Term Investments | G26: =(F$26/$F$5)*G$5 -> #DIV/0! | H26: =(G$26/$F$5)*H$5 -> #DIV/0! | I26: =(H$26/$F$5)*I$5 -> #DIV/0! | J26: =(I$26/$F$5)*J$5 -> #DIV/0! | K26: =(J$26/$F$5)*K$5 -> #DIV/0! | M26: Inventory % Sales
B27: Net Receivables | G27: =(F$27/$F$5)*G$5 -> #DIV/0! | H27: =(G$27/$F$5)*H$5 -> #DIV/0! | I27: =(H$27/$F$5)*I$5 -> #DIV/0! | J27: =(I$27/$F$5)*J$5 -> #DIV/0! | K27: =(J$27/$F$5)*K$5 -> #DIV/0! | M27: Long Term Debt Change
B28: Inventory | G28: =G5*O26 -> 0 | H28: =H5*P26 -> 0 | I28: =I5*Q26 -> 0 | J28: =J5*R26 -> 0 | K28: =K5*S26 -> 0
B29: Prepaid Expenses | G29: =(F$29/$F$5)*G$5 -> #DIV/0! | H29: =(G$29/$F$5)*H$5 -> #DIV/0! | I29: =(H$29/$F$5)*I$5 -> #DIV/0! | J29: =(I$29/$F$5)*J$5 -> #DIV/0! | K29: =(J$29/$F$5)*K$5 -> #DIV/0!
B30: Other Current Assets | G30: =(F$30/$F$5)*G$5 -> #DIV/0! | H30: =(G$30/$F$5)*H$5 -> #DIV/0! | I30: =(H$30/$F$5)*I$5 -> #DIV/0! | J30: =(I$30/$F$5)*J$5 -> #DIV/0! | K30: =(J$30/$F$5)*K$5 -> #DIV/0!
B31: Total Current Assets | G31: =SUM(G25:G30) -> #DIV/0! | H31: =SUM(H25:H30) -> #DIV/0! | I31: =SUM(I25:I30) -> #DIV/0! | J31: =SUM(J25:J30) -> #DIV/0! | K31: =SUM(K25:K30) -> #DIV/0!
B32: Property, Plant & Equipment (Net) | G32: =(F$32/$F$5)*G$5 -> #DIV/0! | H32: =(G$32/$F$5)*H$5 -> #DIV/0! | I32: =(H$32/$F$5)*I$5 -> #DIV/0! | J32: =(I$32/$F$5)*J$5 -> #DIV/0! | K32: =(J$32/$F$5)*K$5 -> #DIV/0!
B33: Goodwill | G33: =(F$33/$F$5)*G$5 -> #DIV/0! | H33: =(G$33/$F$5)*H$5 -> #DIV/0! | I33: =(H$33/$F$5)*I$5 -> #DIV/0! | J33: =(I$33/$F$5)*J$5 -> #DIV/0! | K33: =(J$33/$F$5)*K$5 -> #DIV/0!
B34: Intangible Assets | G34: =(F$34/$F$5)*G$5 -> #DIV/0! | H34: =(G$34/$F$5)*H$5 -> #DIV/0! | I34: =(H$34/$F$5)*I$5 -> #DIV/0! | J34: =(I$34/$F$5)*J$5 -> #DIV/0! | K34: =(J$34/$F$5)*K$5 -> #DIV/0!
B35: Long-Term Investments | G35: =(F$35/$F$5)*G$5 -> #DIV/0! | H35: =(G$35/$F$5)*H$5 -> #DIV/0! | I35: =(H$35/$F$5)*I$5 -> #DIV/0! | J35: =(I$35/$F$5)*J$5 -> #DIV/0! | K35: =(J$35/$F$5)*K$5 -> #DIV/0!
B36: Tax Assets | G36: =(F$36/$F$5)*G$5 -> #DIV/0! | H36: =(G$36/$F$5)*H$5 -> #DIV/0! | I36: =(H$36/$F$5)*I$5 -> #DIV/0! | J36: =(I$36/$F$5)*J$5 -> #DIV/0! | K36: =(J$36/$F$5)*K$5 -> #DIV/0!
B37: Other Non-Current Assets | G37: =(F$37/$F$5)*G$5 -> #DIV/0! | H37: =(G$37/$F$5)*H$5 -> #DIV/0! | I37: =(H$37/$F$5)*I$5 -> #DIV/0! | J37: =(I$37/$F$5)*J$5 -> #DIV/0! | K37: =(J$37/$F$5)*K$5 -> #DIV/0!
B38: Total Non-Current Assets | G38: =(F$38/$F$5)*G$5 -> #DIV/0! | H38: =(G$38/$F$5)*H$5 -> #DIV/0! | I38: =(H$38/$F$5)*I$5 -> #DIV/0! | J38: =(I$38/$F$5)*J$5 -> #DIV/0! | K38: =(J$38/$F$5)*K$5 -> #DIV/0!
B39: Other Assets | G39: =(F$39/$F$5)*G$5 -> #DIV/0! | H39: =(G$39/$F$5)*H$5 -> #DIV/0! | I39: =(H$39/$F$5)*I$5 -> #DIV/0! | J39: =(I$39/$F$5)*J$5 -> #DIV/0! | K39: =(J$39/$F$5)*K$5 -> #DIV/0!
B40: Other Non-Operating Adjustments | G40: =G69-SUM(G32:G39) -> #DIV/0! | H40: =H69-SUM(H32:H39) -> #DIV/0! | I40: =I69-SUM(I32:I39) -> #DIV/0! | J40: =J69-SUM(J32:J39) -> #DIV/0! | K40: =K69-SUM(K32:K39) -> #DIV/0!
B41: Total Long-term Assets | G41: =SUM(G32:G38) -> #DIV/0! | H41: =SUM(H32:H38) -> #DIV/0! | I41: =SUM(I32:I38) -> #DIV/0! | J41: =SUM(J32:J38) -> #DIV/0! | K41: =SUM(K32:K38) -> #DIV/0!
B42: Total Assets | G42: =SUM(G31,G41) -> #DIV/0! | H42: =SUM(H31,H41) -> #DIV/0! | I42: =SUM(I31,I41) -> #DIV/0! | J42: =SUM(J31,J41) -> #DIV/0! | K42: =SUM(K31,K41) -> #DIV/0!
B44: Accounts Payable | G44: =(F$44/$F$5)*G$5 -> #DIV/0! | H44: =(G$44/$F$5)*H$5 -> #DIV/0! | I44: =(H$44/$F$5)*I$5 -> #DIV/0! | J44: =(I$44/$F$5)*J$5 -> #DIV/0! | K44: =(J$44/$F$5)*K$5 -> #DIV/0!
B45: Other Payables | G45: =(F$45/$F$5)*G$5 -> #DIV/0! | H45: =(G$45/$F$5)*H$5 -> #DIV/0! | I45: =(H$45/$F$5)*I$5 -> #DIV/0! | J45: =(I$45/$F$5)*J$5 -> #DIV/0! | K45: =(J$45/$F$5)*K$5 -> #DIV/0!
...

Sheet RV
B2: "Company Name" Relative Valuation
D4: EV/Sales | E4: Price/Sales | F4: Price/Earnings | G4: Price/Book Value | I4: Weight
B5: Company Name | D5: =G16/F16 -> #DIV/0! | E5: =E16/(F16/K16) -> #DIV/0! | F5: =E16/I16 -> #DIV/0! | G5: =E16/(J16/K16) -> #DIV/0! | I5: EV/Sales | J5: 0.25
B6: Competitor | D6: =G17/F17 -> #DIV/0! | E6: =E17/(F17/K17) -> #DIV/0! | F6: =E17/I17 -> #DIV/0! | G6: =E17/(J17/K17) -> #DIV/0! | I6: Price/Sales | J6: 0.25
B7: Competitor | D7: =G18/F18 -> #DIV/0! | E7: =E18/(F18/J18) -> #DIV/0! | F7: =E18/H18 -> #DIV/0! | G7: =E18/(I18/J18) -> #DIV/0! | I7: Price/Earnings | J7: 0.25
B8: Competitor | D8: =G19/F19 -> #DIV/0! | E8: =E19/(F19/J19) -> #DIV/0! | F8: =E19/H19 -> #DIV/0! | G8: =E19/(I19/J19) -> #DIV/0! | I8: Price/Book Value | J8: 0.25
B9: Competitor | D9: =G20/F20 -> #DIV/0! | E9: =E20/(F20/J20) -> #DIV/0! | F9: =E20/H20 -> #DIV/0! | G9: =E20/(I20/J20) -> #DIV/0!
B10: Low | D10: =MIN(D5:D9) -> #DIV/0! | E10: =MIN(E5:E9) -> #DIV/0! | F10: =MIN(F5:F9) -> #DIV/0! | G10: =MIN(G5:G9) -> #DIV/0! | I10: Implied Price Target | J10: =(D13*J5)+(E13*J6)+(F13*J7)+(G13*J8) -> #DIV/0!
B11: Average | D11: =AVERAGE(D5:D9) -> #DIV/0! | E11: =AVERAGE(E5:E9) -> #DIV/0! | F11: =AVERAGE(F5:F9) -> #DIV/0! | G11: =AVERAGE(G5:G9) -> #DIV/0! | I11: Implied Upside/Downside | J11: =(J10/E16)-1 -> #DIV/0!
B12: High | D12: =MAX(D5:D9) -> #DIV/0! | E12: =MAX(E5:E9) -> #DIV/0! | F12: =MAX(F5:F9) -> #DIV/0! | G12: =MAX(G5:G9) -> #DIV/0!
B13: "Company Name" | D13: =(D11*(F16-H16))/K16 -> #DIV/0! | E13: =E11*(F16/K16) -> #DIV/0! | F13: =F11*(I16) -> #DIV/0! | G13: =G11*(J16/K16) -> #DIV/0!
B15: Financials | D15: Market Cap | E15: Share Price | F15: Sales | G15: Enterprise Value | H15: Net Debt | I15: EPS | J15: Book Value | K15: Shares/OS
B16: "Company Name"
B17: Competitor
B18: Competitor
B19: Competitor
B20: Competitor

Sheet Beta Data
B2: Ticker
B3: Benchmark | C3: S&P 500
B4: Lookback (years) | C4: 5
B5: Beta | C5: =SLOPE(E8:E1261,F8:F1261) -> 1.2513681
B6: Date | C6: Ticker Adj Close | D6: Benchmark Adj Close | E6: Ticker Returns | F6: Benchmark Returns
B7: 44168 | C7: 119.67622 | D7: 3666.72
B8: 44169 | C8: 119.00455 | D8: 3699.1201 | E8: {=((C8:C1261/C7:C1260)-1)*100} -> -0.56124484 | F8: {=((D8:D1261/D7:D1260)-1)*100} -> 0.88362751
B9: 44172 | C9: 120.46474 | D9: 3691.96 | E9: 1.2270034 | F9: -0.19356377
B10: 44173 | C10: 121.07798 | D10: 3702.25 | E10: 0.50906441 | F10: 0.27871481
B11: 44174 | C11: 118.54703 | D11: 3672.8201 | E11: -2.0903491 | F11: -0.79492016
B12: 44175 | C12: 119.96826 | D12: 3668.1001 | E12: 1.1988779 | F12: -0.12851081
B13: 44176 | C13: 119.16031 | D13: 3663.46 | E13: -0.67347219 | F13: -0.12649973
B14: 44179 | C14: 118.54703 | D14: 3647.49 | E14: -0.51466907 | F14: -0.4359259
B15: 44180 | C15: 124.48508 | D15: 3694.6201 | E15: 5.0090242 | F15: 1.2921249
B16: 44181 | C16: 124.41692 | D16: 3701.1699 | E16: -0.054748234 | F16: 0.17727952
B17: 44182 | C17: 125.28331 | D17: 3722.48 | E17: 0.69635737 | F17: 0.57576548
B18: 44183 | C18: 123.29747 | D18: 3709.4099 | E18: -1.5850793 | F18: -0.35111185
B19: 44186 | C19: 124.8258 | D19: 3694.9199 | E19: 1.2395453 | F19: -0.39062791
B20: 44187 | C20: 128.37888 | D20: 3687.26 | E20: 2.846429 | F20: -0.20730929
... B1261: 45993 | C1261: 285.5047 | D1261: 6812.71 | E1261: 0.84941489 | F1261: 0.0011754363

Sheet DCF Q
B2: "Company Name" DCF Analysis (UNITS)
B4: WACC | G4: Other Assumptions
B5: Beta | E5: # | G5: Fiscal Year End | J5: 46022
B6: Market Risk Premium | E6: # | G6: LTGR | J6: 0.02
B7: Risk Free Rate | E7: # | G7: Cash & Equivalents | J7: # | L7: 1 year (4 Quarters) historical and forecasted
B8: Cost of Equity | E8: =E7+(E5*E6) -> #VALUE! | G8: Diluted S/O | J8: #
B9: Weight of Equity | E9: =J10/SUM(J10:J11) -> #VALUE! | G9: Current Price | J9: #
B10: Cost of Debt | E10: # | G10: Mkt Cap | J10: =J8*J9 -> #VALUE!
B11: After Tax CoD | E11: =E10*(1-E13) -> #VALUE! | G11: BV debt
B12: Weight of Debt | E12: =1-E9 -> #VALUE! | G12: Financial Units
B13: Tax Rate | E13: #
B14: WACC | E14: =(E9*E8)+(E11*E12) -> #VALUE!
B16: Free Cash Flow | D16: Q1 "YEAR""A" | E16: Q2 "YEAR""A" | F16: Q3 "YEAR""A" | G16: Q4 "YEAR""A" | H16: "####"A | I16: Q1 "YEAR""E" | J16: Q2 "YEAR""E" | K16: Q3 "YEAR""E" | L16: Q4 "YEAR""E" | M16: "####"E
B17: Revenue | D17: HIST | E17: HIST | F17: HIST | G17: HIST | H17: =SUM(D17:G17) -> 0 | I17: Forecast Formula | J17: Forecast Formula | K17: Forecast Formula | L17: Forecast Formula | M17: =SUM(I17:L17) -> 0
B18: Revenue Growth (%) | E18: =IFERROR(E17/D17-1,"") | F18: =IFERROR(F17/E17-1,"") | G18: =IFERROR(G17/F17-1,"") | I18: =I17/H17-1 -> #VALUE! | J18: =J17/I17-1 -> #VALUE! | K18: =K17/J17-1 -> #VALUE! | L18: =L17/K17-1 -> #VALUE!
B19: (-) COGS | D19: HIST | E19: HIST | F19: HIST | G19: HIST | H19: =SUM(D19:G19) -> 0 | M19: =SUM(I19:L19) -> 0
B20: GP | D20: =D17+D19 -> #VALUE! | E20: =E17+E19 -> #VALUE! | F20: =F17+F19 -> #VALUE! | G20: =G17+G19 -> #VALUE! | H20: =H17+H19 -> 0 | I20: =I17+I19 -> #VALUE! | J20: =J17+J19 -> #VALUE! | K20: =K17+K19 -> #VALUE! | ... M20: =M17+M19 -> 0
B21: GP Margin (%) | D21: =D19/D17 -> #VALUE! | E21: =E19/E17 -> #VALUE! | F21: =F19/F17 -> #VALUE! | G21: =G19/G17 -> #VALUE! | H21: =H19/H17 -> #DIV/0! | I21: =I19/I17 -> #VALUE! | J21: =J19/J17 -> #VALUE! | K21: =K19/K17 -> #VALUE! | ... M21: =M19/M17 -> #DIV/0!
B23: (-) Op Ex | D23: HIST | E23: HIST | F23: HIST | G23: HIST | H23: =SUM(D23:G23) -> 0 | I23: Forecast Formula | J23: Forecast Formula | K23: Forecast Formula | L23: Forecast Formula | M23: =SUM(I23:L23) -> 0
B24: EBIT | D24: =D20+D23 -> #VALUE! | E24: =E20+E23 -> #VALUE! | F24: =F20+F23 -> #VALUE! | G24: =G20+G23 -> #VALUE! | H24: =H20+H23 -> 0 | I24: =I20+I23 -> #VALUE! | J24: =J20+J23 -> #VALUE! | K24: =K20+K23 -> #VALUE! | ... M24: =M20+M23 -> 0
B25: EBIT Margin (%) | D25: =D24/D17 -> #VALUE! | E25: =E24/E17 -> #VALUE! | F25: =F24/F17 -> #VALUE! | G25: =G24/G17 -> #VALUE! | H25: =H23/H17 -> #DIV/0! | I25: =I23/I17 -> #VALUE! | J25: =J23/J17 -> #VALUE! | K25: =K23/K17 -> #VALUE! | L25: =L23/L17 -> #VALUE! | M25: =M23/M17 -> #DIV/0!
B27: NOPAT | D27: =D24*(1-$E$13) -> #VALUE! | E27: =E24*(1-$E$13) -> #VALUE! | F27: =F24*(1-$E$13) -> #VALUE! | G27: =G24*(1-$E$13) -> #VALUE! | H27: =H24*(1-$E$13) -> #VALUE! | I27: =I24*(1-$E$13) -> #VALUE! | J27: =J24*(1-$E$13) -> #VALUE! | K27: =K24*(1-$E$13) -> #VALUE! | ... M27: =M24*(1-$E$13) -> #VALUE!
B28: (+) D&A | D28: HIST | E28: HIST | F28: HIST | G28: HIST | H28: =SUM(D28:G28) -> 0 | I28: Forecast Formula | J28: Forecast Formula | K28: Forecast Formula | L28: Forecast Formula | M28: =SUM(I28:L28) -> 0
B29: (-) CapEx | D29: HIST | E29: HIST | F29: HIST | G29: HIST | H29: =SUM(D29:G29) -> 0 | I29: Forecast Formula | J29: Forecast Formula | K29: Forecast Formula | L29: Forecast Formula | M29: =SUM(I29:L29) -> 0
B30: (-) Changes in WC | D30: HIST | E30: HIST | F30: HIST | G30: HIST | H30: =SUM(D30:G30) -> 0 | I30: Forecast Formula | J30: Forecast Formula | K30: Forecast Formula | L30: Forecast Formula | M30: =SUM(I30:L30) -> 0
B31: Unlevered Free Cash Flow | D31: =D27+D28+D29+D30 -> #VALUE! | E31: =E27+E28+E29+E30 -> #VALUE! | F31: =F27+F28+F29+F30 -> #VALUE! | G31: =G27+G28+G29+G30 -> #VALUE! | H31: =H27+H28+H29+H30 -> #VALUE! | I31: =I27+I28+I29+I30 -> #VALUE! | J31: =J27+J28+J29+J30 -> #VALUE! | K31: =K27+K28+K29+K30 -> #VALUE! | ... M31: =M27+M28+M29+M30 -> #VALUE!
B33: DCF | I33: Year"E" | J33: Year"E" | K33: Year"E" | L33: Year"E" | M33: Year"E"
B34: Discount Period | I34: =YEARFRAC(TODAY(),$J$5) -> 0.077777778 | J34: =I34+0.25 -> 0.32777778 | K34: =J34+0.25 -> 0.57777778 | L34: =K34+0.25 -> 0.82777778
B35: Discount Factor | I35: =(1/(1+$E$14))^I34 -> #VALUE! | J35: =(1/(1+$E$14))^J34 -> #VALUE! | K35: =(1/(1+$E$14))^K34 -> #VALUE! | L35: =(1/(1+$E$14))^L34 -> #VALUE!
B37: PV of UFCF | I37: =I31*I35 -> #VALUE! | J37: =J31*J35 -> #VALUE! | K37: =K31*K35 -> #VALUE! | L37: =L31*L35 -> #VALUE! | M37: =SUM(I37:L37) -> #VALUE!
B38: Total PV of UFCF | M38: =SUM(M37) -> #VALUE!
B40: Terminal Value | M40: =(M31*(1+J6))/(E14-F2) -> #VALUE!
B41: PV of TV | M41: =M40*M35 -> #VALUE!
B43: Enterprise Value | M43: =M38+M41 -> #VALUE!
B44: (-) Net Debt | M44: =-($J$11-$J$7) -> #VALUE!
B45: Equity Value | M45: =M43+M44 -> #VALUE!
B47: (/) Shares Outstanding | M47: =J8 -> #
B48: Per Share Price Target | M48: =M45/M47 -> #VALUE!
B49: Implied Upside/Downside | M49: =M48/J9-1 -> #VALUE!

Sheet 3-STMT Q
B2: "Company Name" 3 Statement Model (UNITS)
B4: Income Statement
D5: Q1 "YEAR""A" | E5: Q2 "YEAR""A" | F5: Q3 "YEAR""A" | G5: Q4 "YEAR""A" | H5: "####"A | I5: Q1 "YEAR""E" | J5: Q2 "YEAR""E" | K5: Q3 "YEAR""E" | L5: Q4 "YEAR""E" | M5: "####"E | O5: Assumptions | P5: Type | Q5: Value
B6: Line Item | O6: Revenue | P6: Custom | Q6: 0.02 | R6: 0.04 | S6: 0.03
B7: Line Item | O7: Gross Margin | P7: Step | Q7: 0.005
B8: Gross Income | O8: Operating Costs | P8: Step | Q8: 0.0075
B9: Gross Margin % | O9: EBITDA Margin | P9: Custom | R9: **ford doesn’t report
B10: Line Item | O10: Tax Rate | P10: Constant | Q10: 0.21
B11: Line Item | O11: Interest Rate on Debt | P11: Custom | Q11: 0.06 | R11: 0.05 | S11: 0.04 | T11: 0.07
B12: Operating Income
B13: Operating Margin %
B14: Line Item
B15: Income before Taxes
B16: Income Tax Expense
B17: Net Income
B18: Net Income Margin %
B19: EPS
B21: Balance Sheet
B22: Assets | D22: Q1 "YEAR""A" | E22: Q2 "YEAR""A" | F22: Q3 "YEAR""A" | G22: Q4 "YEAR""A" | H22: "####"A | I22: Q1 "YEAR""E" | J22: Q2 "YEAR""E" | K22: Q3 "YEAR""E" | L22: Q4 "YEAR""E" | M22: "####"E
B23: Line Item
B24: Line Item
B25: Total Current Assets
B26: Line Item
B27: Line Item
B28: Line Item
B29: Line Item
B30: Total Assets
B32: Liabilties
B33: Line Item
B34: Line Item
B35: Line Item
... B51: Cash Flow Statement
B52: Cash Flows from Operating Activities | D52: Q1 "YEAR""A" | E52: Q2 "YEAR""A" | F52: Q3 "YEAR""A" | G52: Q4 "YEAR""A" | H52: "####"A | I52: Q1 "YEAR""E" | J52: Q2 "YEAR""E" | K52: Q3 "YEAR""E" | L52: Q4 "YEAR""E" | M52: "####"E
B53: Line Item
B54: Line Item
B55: Total Current Assets
B56: Line Item
B57: Line Item
B58: Line Item
B59: Line Item
...

Sheet 3-STMT Quarterly
B2: "Company Name" Balance Sheet (UNITS)
B4: Assets | D4: Q1 "YEAR""A" | E4: Q2 "YEAR""A" | F4: Q3 "YEAR""A" | G4: Q4 "YEAR""A" | H4: "####"A | I4: Q1 "YEAR""E" | J4: Q2 "YEAR""E" | K4: Q3 "YEAR""E" | L4: Q4 "YEAR""E" | M4: "####"E
B5: Line Item
B6: Line Item
B7: Total Current Assets
B8: Line Item
B9: Line Item
B10: Line Item
B11: Line Item
B12: Total Assets
B14: Liabilties
B15: Line Item
B16: Line Item
B17: Line Item
... B31: Total Liabilities and Equity

Sheet CF STMT Annual 
B2: "Company Name" Statements of Cash Flows (UNITS)
B4: Cash Flows from Operating Activities | D4: Year"A" | E4: Year"A" | F4: Year"A" | G4: Year"A" | H4: Year"A" | I4: Year"E" | J4: Year"E"
B5: Line Item
B6: Line Item
B7: Total Current Assets
B8: Line Item
B9: Line Item
B10: Line Item
B11: Line Item
B12: Net Cash Provided by/(used in) Operating Activities
B14: Cash Flows from Investing Activities
B15: Line Item
B16: Line Item
B17: Line Item
... B36: Cash, Cash Equivalents, and Restricted Cash at End of Period

Sheet CF STMT Quarterly
B2: "Company Name" Statements of Cash Flows (UNITS)
B4: Cash Flows from Operating Activities | D4: Q1 "YEAR""A" | E4: Q2 "YEAR""A" | F4: Q3 "YEAR""A" | G4: Q4 "YEAR""A" | H4: "####"A | I4: Q1 "YEAR""E" | J4: Q2 "YEAR""E" | K4: Q3 "YEAR""E" | L4: Q4 "YEAR""E" | M4: "####"E
B5: Line Item
B6: Line Item
B7: Total Current Assets
B8: Line Item
B9: Line Item
B10: Line Item
B11: Line Item
B12: Net Cash Provided by/(used in) Operating Activities
B14: Cash Flows from Investing Activities
B15: Line Item
B16: Line Item
B17: Line Item
... B36: Cash, Cash Equivalents, and Restricted Cash at End of Period
