Workbook

Sheet Cover
B2: Microsoft Corporation
B3: MSFT
B4: 12/04/2025

Sheet Summary
B2: Microsoft Corporation
B3: Ticker | C3: MSFT
B4: Current Stock Price | C4: 477.73 | D4: As of 12/04/2025
B5: Weighted Implied Stock Price | C5: =(C9*D9)+(C10*D10) -> 433.58149
B6: Implied Upside/Downside | C6: =(C4/C5-1) -> 0.10182286
B8: Method | C8: Weight | D8: Price Target
B9: DCF | C9: 0.5 | D9: =(C13*D13)+(C14*D14)+(C15*D15) -> 163.13436
B10: Relative Valuation | C10: 0.5 | D10: =(C18*D18)+(C19*D19)+(C20*D20)+(C21*D21) -> 704.02863
B12: DCF Case | C12: Weight | D12: Price Target
B13: Base | C13: 0.6 | D13: ='DCF Base'!K48 -> 274.60786
B14: Bear | C14: 0.2 | D14: ='DCF Bear'!K48 -> -4.0661202
B15: Bull | C15: 0.2 | D15: ='DCF Bull'!K48 -> -4.0856751
B17: Relative Method | C17: Weight | D17: Price Target
B18: EV/Sales | C18: =RV!J5 -> 0.25 | D18: =RV!D13 -> 376.30211
B19: Price/Sales | C19: =RV!J6 -> 0.25 | D19: =RV!E13 -> 375.29697
B20: Price/Earnings | C20: =RV!J7 -> 0.25 | D20: =RV!F13 -> 959.41996
B21: Price/Book Value | C21: =RV!J8 -> 0.25 | D21: =RV!G13 -> 1105.0955

Sheet DCF Base
B2: Microsoft Corporation DCF Analysis
B4: WACC | E4: 0.1 | G4: Other Assumptions
B5: Beta | E5: =Beta!C5 -> 1.1566004 | G5: Fiscal Year End | J5: 46022
B6: Market Risk Premium | E6: 0.0433 | G6: LTGR | J6: 0.025
B7: Risk Free Rate | E7: 0.0406 | G7: Cash & Equivalents | J7: 30242
B8: Cost of Equity | E8: =E7+(E5*E6) -> 0.090680798 | G8: Shares Outstanding | J8: 7465
B9: Weight of Equity | E9: =J10/SUM(J10:J11) -> 0.98322387 | G9: Current Price | J9: 477.73
B10: Cost of Debt | E10: ='3 Statement'!O9 -> 0.05 | G10: Mkt Cap | J10: 3550971.8
B11: After Tax CoD | E11: =E10*(1-E13) -> 0.048 | G11: BV Debt | J11: 60588
B12: Weight of Debt | E12: =1-E9 -> 0.016776131 | G12: Financial Units | J12: USD in millions
B13: Tax Rate | E13: ='3 Statement'!O8 -> 0.04
B14: WACC | E14: =(E9*E8)+(E12*E10*(1-E13)) -> 0.08996478
B16: Free Cash Flow | D16: 2023 A | E16: 2024 A | F16: 2025 A | G16: 2026 E | H16: 2027 E | I16: 2028 E | J16: Year"E" | K16: Year"E"
B17: Revenue | D17: ='3 Statement'!D5 -> 211915 | E17: ='3 Statement'!E5 -> 245122 | F17: ='3 Statement'!F5 -> 281724 | G17: ='3 Statement'!G5 -> 284541.24 | H17: ='3 Statement'!H5 -> 287386.65 | I17: ='3 Statement'!I5 -> 290260.52 | J17: ='3 Statement'!J5 -> 293163.12 | K17: ='3 Statement'!K5 -> 296094.76
B18: Revenue Growth (%) | E18: =E17/D17-1 -> 0.15669962 | F18: =F17/E17-1 -> 0.14932156 | G18: =((1+'3 Statement'!O5)-1)*100 -> 1 | H18: =((1+'3 Statement'!P5)-1)*100 -> 1 | I18: =((1+'3 Statement'!Q5)-1)*100 -> 1 | J18: =((1+'3 Statement'!R5)-1)*100 -> 1 | K18: =((1+'3 Statement'!S5)-1)*100 -> 1
B19: (-) COGS | D19: ='3 Statement'!D6 -> 65863 | E19: ='3 Statement'!E6 -> 74114 | F19: ='3 Statement'!F6 -> 87831 | G19: ='3 Statement'!G6 -> 83018.485 | H19: ='3 Statement'!H6 -> 78100.937 | I19: ='3 Statement'!I6 -> 73076.736 | J19: ='3 Statement'!J6 -> 67944.241 | K19: ='3 Statement'!K6 -> 62701.788
B20: GP | D20: =D17-D19 -> 146052 | E20: =E17-E19 -> 171008 | F20: =F17-F19 -> 193893 | G20: =G17-G19 -> 201522.75 | H20: =H17-H19 -> 209285.72 | I20: =I17-I19 -> 217183.78 | J20: =J17-J19 -> 225218.88 | K20: =K17-K19 -> 233392.97
B21: GP Margin (%) | E21: =E20/D20-1 -> 0.17087065 | F21: =F20/E20-1 -> 0.13382415 | G21: ='3 Statement'!G8 -> 0.70823742 | H21: ='3 Statement'!H8 -> 0.72823742 | I21: ='3 Statement'!I8 -> 0.74823742 | J21: ='3 Statement'!J8 -> 0.76823742 | K21: ='3 Statement'!K8 -> 0.78823742
B23: (-) Op Ex | D23: =SUM('3 Statement'!D9:D11) -> 242768 | E23: =SUM('3 Statement'!E9:E11) -> 269063 | F23: =SUM('3 Statement'!F9:F11) -> 303417 | G23: =SUM('3 Statement'!G9:G11) -> 149133.53 | H23: =SUM('3 Statement'!H9:H11) -> 65680.536 | I23: =SUM('3 Statement'!I9:I11) -> 25960.519 | J23: =SUM('3 Statement'!J9:J11) -> 9217.4147 | K23: =SUM('3 Statement'!K9:K11) -> 2940.7392
B24: EBIT | D24: =D20+D23 -> 388820 | E24: =E20+E23 -> 440071 | F24: =F20+F23 -> 497310 | G24: ='3 Statement'!G12 -> 138349.52 | H24: ='3 Statement'!H12 -> 148354.61 | I24: ='3 Statement'!I12 -> 158545.97 | J24: ='3 Statement'!J12 -> 168926.33 | K24: ='3 Statement'!K12 -> 179498.43
B25: EBIT Margin (%) | D25: =D24/D17 -> 1.8347923 | E25: =E24/E17 -> 1.7953142 | F25: =F24/F17 -> 1.7652383 | G25: ='3 Statement'!G13 -> 0.48621956 | H25: ='3 Statement'!H13 -> 0.51621956 | I25: ='3 Statement'!I13 -> 0.54621956 | J25: ='3 Statement'!J13 -> 0.57621956 | K25: ='3 Statement'!K13 -> 0.60621956
B27: NOPAT | D27: =D24*(1-$E$13) -> 373267.2 | E27: =E24*(1-$E$13) -> 422468.16 | F27: =F24*(1-$E$13) -> 477417.6 | G27: =G24*(1-$E$13) -> 132815.54 | H27: =H24*(1-$E$13) -> 142420.43 | I27: =I24*(1-$E$13) -> 152204.13 | J27: =J24*(1-$E$13) -> 162169.27 | K27: =K24*(1-$E$13) -> 172318.5
B28: (+) D&A | D28: ='3 Statement'!D71 -> 13861 | E28: ='3 Statement'!E71 -> 22287 | F28: ='3 Statement'!F71 -> 34153 | G28: ='3 Statement'!G71 -> 13787.34 | H28: ='3 Statement'!H71 -> 14971.128 | I28: ='3 Statement'!I71 -> 15028.524 | J28: ='3 Statement'!J71 -> 15086.494 | K28: ='3 Statement'!K71 -> 15145.044
B29: (-) CapEx | D29: ='3 Statement'!D78 -> -28107 | E29: ='3 Statement'!E78 -> -44477 | F29: ='3 Statement'!F78 -> -64551 | G29: ='3 Statement'!G78 -> -9 | H29: ='3 Statement'!H78 -> -9 | I29: ='3 Statement'!I78 -> -9 | J29: ='3 Statement'!J78 -> -9 | K29: ='3 Statement'!K78 -> -9
B30: (-) Changes in WC | D30: ='3 Statement'!D74 -> -2388 | E30: ='3 Statement'!E74 -> 1824 | F30: ='3 Statement'!F74 -> -5350 | G30: ='3 Statement'!G74 -> -18932.527 | H30: ='3 Statement'!H74 -> -151.34527 | I30: ='3 Statement'!I74 -> -152.85872 | J30: ='3 Statement'!J74 -> -154.38731 | K30: ='3 Statement'!K74 -> -155.93118
B31: Unlevered Free Cash Flow | D31: =D27+D28+D29+D30 -> 356633.2 | E31: =E27+E28+E29+E30 -> 402102.16 | F31: =F27+F28+F29+F30 -> 441669.6 | G31: =G27+G28+G29+G30 -> 127661.35 | H31: =H27+H28+H29+H30 -> 157231.21 | I31: =I27+I28+I29+I30 -> 167070.8 | J31: =J27+J28+J29+J30 -> 177092.38 | K31: =K27+K28+K29+K30 -> 187298.61
B33: DCF | G33: 2026 E | H33: 2027 E | I33: 2028 E | J33: Year"E" | K33: Year"E"
B34: Discount Period | G34: =YEARFRAC(TODAY(),$J$5) -> 0.075 | H34: =G34+1 -> 1.075 | I34: =H34+1 -> 2.075 | J34: =I34+1 -> 3.075 | K34: =J34+1 -> 4.075
B35: Discount Factor | G35: =(1/(1+$E$14))^G34 -> 0.99355992 | H35: =(1/(1+$E$14))^H34 -> 0.91155232 | I35: =(1/(1+$E$14))^I34 -> 0.83631355 | J35: =(1/(1+$E$14))^J34 -> 0.76728493 | K35: =(1/(1+$E$14))^K34 -> 0.70395388
B37: PV of UFCF | G37: =G31*G35 -> 126839.2 | H37: =H31*H35 -> 143324.47 | I37: =I31*I35 -> 139723.57 | J37: =J31*J35 -> 135880.32 | K37: =K31*K35 -> 131849.58
B38: Total PV of UFCF | K38: =SUM(G37:K37) -> 677617.15
B40: Terminal Value | K40: =(K31*(1+J6))/(E14-J6) -> 2955156.2
B41: PV of TV | K41: =K40*K35 -> 2080293.7
B43: Enterprise Value | K43: =K41+K38 -> 2757910.8
B44: (-) Net Debt | K44: =J11-J7 -> 30346
B45: Equity Value | K45: =K41-K44 -> 2049947.7
B47: (/) Shares Outstanding | K47: =J8 -> 7465
B48: Per Share Price Target | K48: =K45/K47 -> 274.60786
B49: Implied Upside/Downside | K49: =(K48/J9-1) -> -0.42518188
B51: Sensitivity Analysis
...

Sheet DCF Bear
B2: Microsoft Corporation DCF Analysis
B4: WACC | E4: 0.1 | G4: Other Assumptions
B5: Beta | E5: 1.2 | G5: Fiscal Year End | J5: 46022
B6: Market Risk Premium | E6: 0.0433 | G6: LTGR | J6: 0.025
B7: Risk Free Rate | E7: 0.0406 | G7: Cash & Equivalents | J7: ='DCF Base'!J7 -> 30242
B8: Cost of Equity | E8: =E7+(E5*E6) -> 0.09256 | G8: Diluted S/O | J8: ='DCF Base'!J8 -> 7465
B9: Weight of Equity | E9: =J10/SUM(J10:J11) -> 0.98329456 | G9: Current Price | J9: ='DCF Base'!J9 -> 477.73
B10: Cost of Debt | E10: ='3 Statement'!O9 -> 0.05 | G10: Mkt Cap | J10: =J8*J9 -> 3566254.5
B11: After Tax CoD | E11: =E10*(1-E13) -> 0.048 | G11: BV Debt | J11: ='DCF Base'!J11 -> 60588
B12: Weight of Debt | E12: =1-E9 -> 0.01670544 | G12: Financial Units | J12: USD in millions
B13: Tax Rate | E13: ='3 Statement'!O8 -> 0.04
B14: WACC | E14: =(E9*E8)+(E12*E10*(1-E13)) -> 0.091815606
B16: Free Cash Flow | D16: 2023 A | E16: 2024 A | F16: 2025 A | G16: 2026 E | H16: 2027 E | I16: 2028 E | J16: Year"E" | K16: Year"E"
B17: Revenue | D17: ='3 Statement'!D5 -> 211915 | E17: ='3 Statement'!E5 -> 245122 | F17: ='3 Statement'!F5 -> 281724 | G17: =F17*G18 -> 33806.88 | H17: =G17*H18 -> 4056.8256 | I17: =H17*I18 -> 486.81907 | J17: =I17*J18 -> 58.418289 | K17: =J17*K18 -> 7.0101946
B18: Revenue Growth (%) | E18: =E17/D17-1 -> 0.15669962 | F18: =F17/E17-1 -> 0.14932156 | G18: =0.12 -> 0.12 | H18: =0.12 -> 0.12 | I18: =0.12 -> 0.12 | J18: =0.12 -> 0.12 | K18: =0.12 -> 0.12
B19: (-) COGS | D19: ='3 Statement'!D6 -> 65863 | E19: ='3 Statement'!E6 -> 74114 | F19: ='3 Statement'!F6 -> 87831 | G19: =G17*G21 -> 4394.8944 | H19: =H17*H21 -> 527.38733 | I19: =I17*I21 -> 63.286479 | J19: =J17*J21 -> 7.5943775 | K19: =K17*K21 -> 0.9113253
B20: GP | D20: =D17-D19 -> 146052 | E20: =E17-E19 -> 171008 | F20: =F17-F19 -> 193893 | G20: =G17-G19 -> 29411.986 | H20: =H17-H19 -> 3529.4383 | I20: =I17-I19 -> 423.53259 | J20: =J17-J19 -> 50.823911 | K20: =K17-K19 -> 6.0988693
B21: GP Margin (%) | E21: =E20/D20-1 -> 0.17087065 | F21: =F20/E20-1 -> 0.13382415 | G21: =0.13 -> 0.13 | H21: =0.13 -> 0.13 | I21: =0.13 -> 0.13 | J21: =0.13 -> 0.13 | K21: =0.13 -> 0.13
B23: (-) Op Ex | D23: =SUM('3 Statement'!D9:D11) -> 242768 | E23: =SUM('3 Statement'!E9:E11) -> 269063 | F23: =SUM('3 Statement'!F9:F11) -> 303417 | G23: =G17*G25 -> 4732.9632 | H23: =H17*H25 -> 567.95558 | I23: =I17*I25 -> 68.15467 | J23: =J17*J25 -> 8.1785604 | K23: =K17*K25 -> 0.98142725
B24: EBIT | D24: =D20+D23 -> 388820 | E24: =E20+E23 -> 440071 | F24: =F20+F23 -> 497310 | G24: =G21-G23 -> -4732.8332 | H24: =H21-H23 -> -567.82558 | I24: =I21-I23 -> -68.02467 | J24: =J21-J23 -> -8.0485604 | K24: =K21-K23 -> -0.85142725
B25: EBIT Margin (%) | D25: =D24/D17 -> 1.8347923 | E25: =E24/E17 -> 1.7953142 | F25: =F24/F17 -> 1.7652383 | G25: =0.14 -> 0.14 | H25: =0.14 -> 0.14 | I25: =0.14 -> 0.14 | J25: =0.14 -> 0.14 | K25: =0.14 -> 0.14
B27: NOPAT | D27: =D24*(1-$E$13) -> 373267.2 | E27: =E24*(1-$E$13) -> 422468.16 | F27: =F24*(1-$E$13) -> 477417.6 | G27: =G24*(1-$E$13) -> -4543.5199 | H27: =H24*(1-$E$13) -> -545.11256 | I27: =I24*(1-$E$13) -> -65.303683 | J27: =J24*(1-$E$13) -> -7.726618 | K27: =K24*(1-$E$13) -> -0.81737016
B28: (+) D&A | D28: ='3 Statement'!D71 -> 13861 | E28: ='3 Statement'!E71 -> 22287 | F28: ='3 Statement'!F71 -> 34153 | G28: =0.16*G17 -> 5409.1008 | H28: =0.16*H17 -> 649.0921 | I28: =0.16*I17 -> 77.891052 | J28: =0.16*J17 -> 9.3469262 | K28: =0.16*K17 -> 1.1216311
B29: (-) CapEx | D29: ='3 Statement'!D78 -> -28107 | E29: ='3 Statement'!E78 -> -44477 | F29: ='3 Statement'!F78 -> -64551 | G29: =-0.17*G17 -> -5747.1696 | H29: =-0.17*H17 -> -689.66035 | I29: =-0.17*I17 -> -82.759242 | J29: =-0.17*J17 -> -9.9311091 | K29: =-0.17*K17 -> -1.1917331
B30: (-) Changes in WC | D30: ='3 Statement'!D74 -> -2388 | E30: ='3 Statement'!E74 -> 1824 | F30: ='3 Statement'!F74 -> -5350 | G30: =0.18 -> 0.18 | H30: =0.18 -> 0.18 | I30: =0.18 -> 0.18 | J30: =0.18 -> 0.18 | K30: =0.18 -> 0.18
B31: Unlevered Free Cash Flow | D31: =D27+D28+D29+D30 -> 356633.2 | E31: =E27+E28+E29+E30 -> 402102.16 | F31: =F27+F28+F29+F30 -> 441669.6 | G31: =G27+G28+G29+G30 -> -4881.4087 | H31: =H27+H28+H29+H30 -> -585.50082 | I31: =I27+I28+I29+I30 -> -69.991874 | J31: =J27+J28+J29+J30 -> -8.1308009 | K31: =K27+K28+K29+K30 -> -0.70747211
B33: DCF | G33: 2026 E | H33: 2027 E | I33: 2028 E | J33: Year"E" | K33: Year"E"
B34: Discount Period | G34: =YEARFRAC(TODAY(),$J$5) -> 0.075 | H34: =G34+1 -> 1.075 | I34: =H34+1 -> 2.075 | J34: =I34+1 -> 3.075 | K34: =J34+1 -> 4.075
B35: Discount Factor | G35: =(1/(1+$E$14))^G34 -> 0.9934335 | H35: =(1/(1+$E$14))^H34 -> 0.90989128 | I35: =(1/(1+$E$14))^I34 -> 0.8333745 | J35: =(1/(1+$E$14))^J34 -> 0.76329235 | K35: =(1/(1+$E$14))^K34 -> 0.69910372
B37: PV of UFCF | G37: =G31*G35 -> -4849.3549 | H37: =H31*H35 -> -532.74209 | I37: =I31*I35 -> -58.329443 | J37: =J31*J35 -> -6.2061781 | K37: =K31*K35 -> -0.49459638
B38: Total PV of UFCF | K38: =SUM(G37:K37) -> -5447.1272
B40: Terminal Value | K40: =(K31*(1+J6))/(E14-J6) -> -10.853137
B41: PV of TV | K41: =K40*K35 -> -7.5874683
B43: Enterprise Value | K43: =K41+K38 -> -5454.7147
B44: (-) Net Debt | K44: =J11-J7 -> 30346
B45: Equity Value | K45: =K41-K44 -> -30353.587
B47: (/) Shares Outstanding | K47: =J8 -> 7465
B48: Per Share Price Target | K48: =K45/K47 -> -4.0661202
B49: Implied Upside/Downside | K49: =(K48/J9-1) -> -1.0085113
B51: Sensitivity Analysis
...

Sheet DCF Bull
B2: Microsoft Corporation DCF Analysis
B4: WACC | E4: 0.1 | G4: Other Assumptions
B5: Beta | E5: 1.2 | G5: Fiscal Year End | J5: 46022
B6: Market Risk Premium | E6: 0.0433 | G6: LTGR | J6: 0.025
B7: Risk Free Rate | E7: 0.0406 | G7: Cash & Equivalents | J7: ='DCF Base'!J7 -> 30242
B8: Cost of Equity | E8: =E7+(E5*E6) -> 0.09256 | G8: Diluted S/O | J8: ='DCF Base'!J8 -> 7465
B9: Weight of Equity | E9: =J10/SUM(J10:J11) -> 0.98329456 | G9: Current Price | J9: ='DCF Base'!J9 -> 477.73
B10: Cost of Debt | E10: ='3 Statement'!O9 -> 0.05 | G10: Mkt Cap | J10: =J8*J9 -> 3566254.5
B11: After Tax CoD | E11: =E10*(1-E13) -> 0.048 | G11: BV Debt | J11: ='DCF Base'!J11 -> 60588
B12: Weight of Debt | E12: =1-E9 -> 0.01670544 | G12: Financial Units | J12: USD in millions
B13: Tax Rate | E13: ='3 Statement'!O8 -> 0.04
B14: WACC | E14: =(E9*E8)+(E12*E10*(1-E13)) -> 0.091815606
B16: Free Cash Flow | D16: 2023 A | E16: 2024 A | F16: 2025 A | G16: 2026 E | H16: 2027 E | I16: 2028 E | J16: Year"E" | K16: Year"E"
B17: Revenue | D17: ='3 Statement'!D5 -> 211915 | E17: ='3 Statement'!E5 -> 245122 | F17: ='3 Statement'!F5 -> 281724 | G17: =F17*G18 -> 53527.56 | H17: =G17*H18 -> 10170.236 | I17: =H17*I18 -> 1932.3449 | J17: =I17*J18 -> 367.14553 | K17: =J17*K18 -> 69.757651
B18: Revenue Growth (%) | E18: =E17/D17-1 -> 0.15669962 | F18: =F17/E17-1 -> 0.14932156 | G18: =0.19 -> 0.19 | H18: =0.19 -> 0.19 | I18: =0.19 -> 0.19 | J18: =0.19 -> 0.19 | K18: =0.19 -> 0.19
B19: (-) COGS | D19: ='3 Statement'!D6 -> 65863 | E19: ='3 Statement'!E6 -> 74114 | F19: ='3 Statement'!F6 -> 87831 | G19: =G17*G21 -> 10705.512 | H19: =H17*H21 -> 2034.0473 | I19: =I17*I21 -> 386.46898 | J19: =J17*J21 -> 73.429107 | K19: =K17*K21 -> 13.95153
B20: GP | D20: =D17-D19 -> 146052 | E20: =E17-E19 -> 171008 | F20: =F17-F19 -> 193893 | G20: =G17-G19 -> 42822.048 | H20: =H17-H19 -> 8136.1891 | I20: =I17-I19 -> 1545.8759 | J20: =J17-J19 -> 293.71643 | K20: =K17-K19 -> 55.806121
B21: GP Margin (%) | E21: =E20/D20-1 -> 0.17087065 | F21: =F20/E20-1 -> 0.13382415 | G21: =0.2 -> 0.2 | H21: =0.2 -> 0.2 | I21: =0.2 -> 0.2 | J21: =0.2 -> 0.2 | K21: =0.2 -> 0.2
B23: (-) Op Ex | D23: =SUM('3 Statement'!D9:D11) -> 242768 | E23: =SUM('3 Statement'!E9:E11) -> 269063 | F23: =SUM('3 Statement'!F9:F11) -> 303417 | G23: =G17*G25 -> 11240.788 | H23: =H17*H25 -> 2135.7496 | I23: =I17*I25 -> 405.79243 | J23: =J17*J25 -> 77.100562 | K23: =K17*K25 -> 14.649107
B24: EBIT | D24: =D20+D23 -> 388820 | E24: =E20+E23 -> 440071 | F24: =F20+F23 -> 497310 | G24: =G21-G23 -> -11240.588 | H24: =H21-H23 -> -2135.5496 | I24: =I21-I23 -> -405.59243 | J24: =J21-J23 -> -76.900562 | K24: =K21-K23 -> -14.449107
B25: EBIT Margin (%) | D25: =D24/D17 -> 1.8347923 | E25: =E24/E17 -> 1.7953142 | F25: =F24/F17 -> 1.7652383 | G25: =0.21 -> 0.21 | H25: =0.21 -> 0.21 | I25: =0.21 -> 0.21 | J25: =0.21 -> 0.21 | K25: =0.21 -> 0.21
B27: NOPAT | D27: =D24*(1-$E$13) -> 373267.2 | E27: =E24*(1-$E$13) -> 422468.16 | F27: =F24*(1-$E$13) -> 477417.6 | G27: =G24*(1-$E$13) -> -10790.964 | H27: =H24*(1-$E$13) -> -2050.1277 | I27: =I24*(1-$E$13) -> -389.36874 | J27: =J24*(1-$E$13) -> -73.82454 | K27: =K24*(1-$E$13) -> -13.871143
B28: (+) D&A | D28: ='3 Statement'!D71 -> 13861 | E28: ='3 Statement'!E71 -> 22287 | F28: ='3 Statement'!F71 -> 34153 | G28: =0.23*G17 -> 12311.339 | H28: =0.23*H17 -> 2339.1544 | I28: =0.23*I17 -> 444.43933 | J28: =0.23*J17 -> 84.443473 | K28: =0.23*K17 -> 16.04426 | M28: *
B29: (-) CapEx | D29: ='3 Statement'!D78 -> -28107 | E29: ='3 Statement'!E78 -> -44477 | F29: ='3 Statement'!F78 -> -64551 | G29: =-0.24*G17 -> -12846.614 | H29: =-0.24*H17 -> -2440.8567 | I29: =-0.24*I17 -> -463.76278 | J29: =-0.24*J17 -> -88.114928 | K29: =-0.24*K17 -> -16.741836
B30: (-) Changes in WC | D30: ='3 Statement'!D74 -> -2388 | E30: ='3 Statement'!E74 -> 1824 | F30: ='3 Statement'!F74 -> -5350 | G30: =0.25 -> 0.25 | H30: =0.25 -> 0.25 | I30: =0.25 -> 0.25 | J30: =0.25 -> 0.25 | K30: =0.25 -> 0.25
B31: Unlevered Free Cash Flow | D31: =D27+D28+D29+D30 -> 356633.2 | E31: =E27+E28+E29+E30 -> 402102.16 | F31: =F27+F28+F29+F30 -> 441669.6 | G31: =G27+G28+G29+G30 -> -11325.99 | H31: =H27+H28+H29+H30 -> -2151.58 | I31: =I27+I28+I29+I30 -> -408.44218 | J31: =J27+J28+J29+J30 -> -77.245995 | K31: =K27+K28+K29+K30 -> -14.318719
B33: DCF | G33: 2026 E | H33: 2027 E | I33: 2028 E | J33: Year"E" | K33: Year"E"
B34: Discount Period | G34: =YEARFRAC(TODAY(),$J$5) -> 0.075 | H34: =G34+1 -> 1.075 | I34: =H34+1 -> 2.075 | J34: =I34+1 -> 3.075 | K34: =J34+1 -> 4.075
B35: Discount Factor | G35: =(1/(1+$E$14))^G34 -> 0.9934335 | H35: =(1/(1+$E$14))^H34 -> 0.90989128 | I35: =(1/(1+$E$14))^I34 -> 0.8333745 | J35: =(1/(1+$E$14))^J34 -> 0.76329235 | K35: =(1/(1+$E$14))^K34 -> 0.69910372
B37: PV of UFCF | G37: =G31*G35 -> -11251.618 | H37: =H31*H35 -> -1957.7039 | I37: =I31*I35 -> -340.3853 | J37: =J31*J35 -> -58.961277 | K37: =K31*K35 -> -10.01027
B38: Total PV of UFCF | K38: =SUM(G37:K37) -> -13618.678
B40: Terminal Value | K40: =(K31*(1+J6))/(E14-J6) -> -219.65957
B41: PV of TV | K41: =K40*K35 -> -153.56482
B43: Enterprise Value | K43: =K41+K38 -> -13772.243
B44: (-) Net Debt | K44: =J11-J7 -> 30346
B45: Equity Value | K45: =K41-K44 -> -30499.565
B47: (/) Shares Outstanding | K47: =J8 -> 7465
B48: Per Share Price Target | K48: =K45/K47 -> -4.0856751
B49: Implied Upside/Downside | K49: =(K48/J9-1) -> -1.0085523
B51: Sensitivity Analysis
...

Sheet 3 Statement
ZZ1: model_role
B2: Microsoft Corporation 3 Statement Model (millions)
B4: Income Statement | D4: 2023 A | E4: 2024 A | F4: 2025 A | G4: 2026 E | H4: 2027 E | I4: 2028 E | J4: 2029 E | K4: 2030 E | M4: Assumptions | N4: Type | O4: Value
B5: Revenue | D5: 211915 | E5: 245122 | F5: 281724 | G5: =F5*(1+O5) -> 284541.24 | H5: =G5*(1+P5) -> 287386.65 | I5: =H5*(1+Q5) -> 290260.52 | J5: =I5*(1+R5) -> 293163.12 | K5: =J5*(1+S5) -> 296094.76 | M5: Revenue | N5: constant | O5: 0.01 | P5: 0.01 | Q5: 0.01 | R5: 0.01 | S5: 0.01 | V5: 416161000000 | ZZ5: IS_REVENUE
B6: Cost of Revenue | D6: 65863 | E6: 74114 | F6: 87831 | G6: =G5-G7 -> 83018.485 | H6: =H5-H7 -> 78100.937 | I6: =I5-I7 -> 73076.736 | J6: =J5-J7 -> 67944.241 | K6: =K5-K7 -> 62701.788 | M6: Gross Margin | N6: constant | O6: 0.02 | P6: 0.02 | Q6: 0.02 | R6: 0.02 | S6: 0.02 | V6: 220960000000 | Y6: "researchAndDevelopmentExpenses": 34550000000, | ZZ6: IS_COGS
B7: Gross Profit | D7: 146052 | E7: 171008 | F7: 193893 | G7: =G8*G5 -> 201522.75 | H7: =H8*H5 -> 209285.72 | I7: =I8*I5 -> 217183.78 | J7: =J8*J5 -> 225218.88 | K7: =K8*K5 -> 233392.97 | M7: Operating Margin | N7: constant | O7: 0.03 | P7: 0.03 | Q7: 0.03 | R7: 0.03 | S7: 0.03 | V7: 195201000000 | Y7: "generalAndAdministrativeExpenses": 0, | ZZ7: IS_GROSS_PROFIT
B8: Gross Margin % | D8: =D7/D5 -> 0.68920086 | E8: =E7/E5 -> 0.69764444 | F8: =F7/F5 -> 0.68823742 | G8: =F8+(O6) -> 0.70823742 | H8: =G8+(P6) -> 0.72823742 | I8: =H8+(Q6) -> 0.74823742 | J8: =I8+(R6) -> 0.76823742 | K8: =J8+(S6) -> 0.78823742 | M8: Tax Rate | N8: constant | O8: 0.04 | P8: 0.04 | Q8: 0.04 | R8: 0.04 | S8: 0.04 | V8: 34550000000 | Y8: "sellingAndMarketingExpenses": 0, | ZZ8: BS_ACCOUNTS_RECEIVABLE
B9: Research & Development Expenses | D9: 97376 | E9: 113848 | F9: 139810 | G9: =(F9/F12)*(G7-G12) -> 68718.492 | H9: =(G9/G12)*(H7-H12) -> 30264.605 | I9: =(H9/H12)*(I7-I12) -> 11962.218 | J9: =(I9/I12)*(J7-J12) -> 4247.2464 | K9: =(J9/J12)*(K7-K12) -> 1355.0485 | M9: Interest Rate on Debt | N9: constant | O9: 0.05 | P9: 0.05 | Q9: 0.05 | R9: 0.05 | S9: 0.05 | V9: 0 | Y9: "sellingGeneralAndAdministrativeExpenses": 27601000000, | ZZ9: BS_ACCOUNTS_RECEIVABLE
B10: Selling, General & Administrative Expenses (SG&A) | D10: 145392 | E10: 155215 | F10: 163607 | G10: =(F10/F12)*(G7-G12) -> 80415.037 | H10: =(G10/G12)*(H7-H12) -> 35415.931 | I10: =(H10/H12)*(I7-I12) -> 13998.302 | J10: =(I10/I12)*(J7-J12) -> 4970.1683 | K10: =(J10/J12)*(K7-K12) -> 1585.6907 | V10: 0 | Y10: "otherExpenses": 0, | ZZ10: IS_OPERATING_EXPENSE
B11: Other Expenses | D11: 0 | E11: 0 | F11: 0 | G11: =(F11/F12)*(G7-G12) -> 0 | H11: =(G11/G12)*(H7-H12) -> 0 | I11: =(H11/H12)*(I7-I12) -> 0 | J11: =(I11/I12)*(J7-J12) -> 0 | K11: =(J11/J12)*(K7-K12) -> 0 | V11: 27601000000 | Y11: "operatingExpenses": 62151000000,
B12: Operating Profit | D12: 88523 | E12: 109433 | F12: 128528 | G12: =G13*G5 -> 138349.52 | H12: =H13*H5 -> 148354.61 | I12: =I13*I5 -> 158545.97 | J12: =J13*J5 -> 168926.33 | K12: =K13*K5 -> 179498.43 | ZZ12: IS_OPERATING_INCOME
B13: Operating Margin % | D13: =D12/D5 -> 0.41772881 | E13: =E12/E5 -> 0.446443 | F13: =F12/F5 -> 0.45621956 | G13: =F13+O7 -> 0.48621956 | H13: =G13+P7 -> 0.51621956 | I13: =H13+Q7 -> 0.54621956 | J13: =I13+R7 -> 0.57621956 | K13: =J13+S7 -> 0.60621956 | ZZ13: BS_ACCOUNTS_RECEIVABLE
B14: Net Interest Income | D14: 1026 | E14: 222 | F14: 262 | G14: =($F$14/$F$5)*G5 -> 264.62 | H14: =($F$14/$F$5)*H5 -> 267.2662 | I14: =($F$14/$F$5)*I5 -> 269.93886 | J14: =($F$14/$F$5)*J5 -> 272.63825 | K14: =($F$14/$F$5)*K5 -> 275.36463 | ZZ14: IS_NON_OPERATING_INCOME
B15: Other Non Operating Expenses | D15: 145392 | E15: 155215 | F15: 163607 | G15: =F15 -> 163607 | H15: =G15 -> 163607 | I15: =H15 -> 163607 | J15: =I15 -> 163607 | K15: =J15 -> 163607 | ZZ15: IS_OPERATING_EXPENSE
B16: Income Before Taxes | D16: 89311 | E16: 107787 | F16: 123627 | G16: =G12-G14-G15 -> -25522.103 | H16: =H12-H14-H15 -> -15519.654 | I16: =I12-I14-I15 -> -5330.9652 | J16: =J12-J14-J15 -> 5046.6888 | K16: =K12-K14-K15 -> 15616.068 | ZZ16: IS_OPERATING_INCOME
B17: Income Tax Expense | D17: 16950 | E17: 19651 | F17: 21795 | G17: =G16*O9 -> -1276.1051 | H17: =H16*P9 -> -775.98271 | I17: =I16*Q9 -> -266.54826 | J17: =J16*R9 -> 252.33444 | K17: =K16*S9 -> 780.80342 | ZZ17: IS_TAX_EXPENSE
B18: Net Income | D18: 144722 | E18: 176272 | F18: 203664 | G18: =G16-G17 -> -24245.998 | H18: =H16-H17 -> -14743.672 | I18: =I16-I17 -> -5064.417 | J18: =J16-J17 -> 4794.3544 | K18: =K16-K17 -> 14835.265 | ZZ18: IS_NET_INCOME
B19: Net Income Margin % | G19: =G18/G5 -> -0.085210839 | H19: =H18/H5 -> -0.051302562 | I19: =I18/I5 -> -0.017447833 | J19: =J18/J5 -> 0.016353879 | K19: =K18/K5 -> 0.050103099 | ZZ19: IS_NET_INCOME
B20: EPS | D20: 9.72e-06 | E20: 1.186e-05 | F20: 1.37e-05 | G20: =G18/G21 -> -0.17343346 | H20: =H18/H21 -> -0.10547014 | I20: =I18/I21 -> -0.036231342 | J20: =J18/J21 -> 0.034301741 | K20: =K18/K21 -> 0.10614815 | ZZ20: IS_NET_INCOME
B21: Weighted Average Shares Outstanding | D21: 97376 | E21: 113848 | F21: 139810 | G21: =F21+O70 -> 139800 | H21: =G21+P70 -> 139790 | I21: =H21+Q70 -> 139780 | J21: =I21+R70 -> 139770 | K21: =J21+S70 -> 139760 | ZZ21: BS_ACCOUNTS_RECEIVABLE
B24: Balance Sheet | D24: 2023 A | E24: 2024 A | F24: 2025 A | G24: 2026 E | H24: 2027 E | I24: 2028 E | J24: 2029 E | K24: 2030 E | M24: Assumptions | N24: Type | O24: Value
B25: Cash & Cash Equivalents | D25: 34704 | E25: 18315 | F25: 30242 | G25: =G101 -> 17262.795 | H25: =H101 -> 32963.726 | I25: =I101 -> 57602.979 | J25: =J101 -> 91351.224 | K25: =K101 -> 134382.03 | M25: Depreciation % of PPE | N25: constant | O25: 0.06 | P25: 0.06 | Q25: 0.06 | R25: 0.06 | S25: 0.06 | ZZ25: BS_CASH
B26: Short-Term Investments | D26: 76552 | E26: 57216 | F26: 64323 | G26: =(F26/F$5)*G$5 -> 64966.23 | H26: =(G26/G$5)*H$5 -> 65615.892 | I26: =(H26/H$5)*I$5 -> 66272.051 | J26: =(I26/I$5)*J$5 -> 66934.772 | K26: =(J26/J$5)*K$5 -> 67604.119 | M26: Inventory % Sales | N26: constant | O26: 0.07 | P26: 0.07 | Q26: 0.07 | R26: 0.07 | S26: 0.07
B27: Net Receivables | D27: 48688 | E27: 56924 | F27: 69905 | G27: =(F27/F$5)*G$5 -> 70604.05 | H27: =(G27/G$5)*H$5 -> 71310.091 | I27: =(H27/H$5)*I$5 -> 72023.191 | J27: =(I27/I$5)*J$5 -> 72743.423 | K27: =(J27/J$5)*K$5 -> 73470.858 | M27: Long Term Debt Change | N27: constant | O27: 0.06 | P27: 0.06 | Q27: 0.06 | R27: 0.06 | S27: 0.06
B28: Inventory | D28: 2500 | E28: 1246 | F28: 938 | G28: =G5*O26 -> 19917.887 | H28: =H5*P26 -> 20117.066 | I28: =I5*Q26 -> 20318.236 | J28: =J5*R26 -> 20521.419 | K28: =K5*S26 -> 20726.633 | ZZ28: BS_INVENTORY
B29: Prepaid Expenses | D29: 0 | E29: 0 | F29: 0 | G29: =(F29/F$5)*G$5 -> 0 | H29: =(G29/G$5)*H$5 -> 0 | I29: =(H29/H$5)*I$5 -> 0 | J29: =(I29/I$5)*J$5 -> 0 | K29: =(J29/J$5)*K$5 -> 0
B30: Other Current Assets | D30: 21813 | E30: 26033 | F30: 25723 | G30: =(F30/F$5)*G$5 -> 25980.23 | H30: =(G30/G$5)*H$5 -> 26240.032 | I30: =(H30/H$5)*I$5 -> 26502.433 | J30: =(I30/I$5)*J$5 -> 26767.457 | K30: =(J30/J$5)*K$5 -> 27035.132
B31: Total Current Assets | D31: 184257 | E31: 159734 | F31: 191131 | G31: =SUM(G25:G30) -> 198731.19 | H31: =SUM(H25:H30) -> 216246.81 | I31: =SUM(I25:I30) -> 242718.89 | J31: =SUM(J25:J30) -> 278318.29 | K31: =SUM(K25:K30) -> 323218.77
B32: Property, Plant & Equipment (Net) | D32: 109987 | E32: 154552 | F32: 229789 | G32: =F32-G81-G74 -> 249518.81 | H32: =G32-H81-H74 -> 250475.4 | I32: =H32-I81-I74 -> 251441.57 | J32: =I32-J81-J74 -> 252417.39 | K32: =J32-K81-K74 -> 253402.98
B33: Goodwill | D33: 67886 | E33: 119220 | F33: 119509 | G33: =F33 -> 119509 | H33: =G33 -> 119509 | I33: =H33 -> 119509 | J33: =I33 -> 119509 | K33: =J33 -> 119509
B34: Intangible Assets | D34: 9366 | E34: 27597 | F34: 22604 | G34: =F34 -> 22604 | H34: =G34 -> 22604 | I34: =H34 -> 22604 | J34: =I34 -> 22604 | K34: =J34 -> 22604
B35: Long-Term Investments | D35: 9879 | E35: 14600 | F35: 15405 | G35: =(F35/F$5)*G$5 -> 15559.05 | H35: =(G35/G$5)*H$5 -> 15714.64 | I35: =(H35/H$5)*I$5 -> 15871.787 | J35: =(I35/I$5)*J$5 -> 16030.505 | K35: =(J35/J$5)*K$5 -> 16190.81
B36: Tax Assets | D36: 0 | E36: 0 | F36: 0 | G36: =(F36/F$5)*G$5 -> 0 | H36: =(G36/G$5)*H$5 -> 0 | I36: =(H36/H$5)*I$5 -> 0 | J36: =(I36/I$5)*J$5 -> 0 | K36: =(J36/J$5)*K$5 -> 0
B37: Other Non-Current Assets | D37: 30601 | E37: 36460 | F37: 40565 | G37: =(F37/F$5)*G$5 -> 40970.65 | H37: =(G37/G$5)*H$5 -> 41380.357 | I37: =(H37/H$5)*I$5 -> 41794.16 | J37: =(I37/I$5)*J$5 -> 42212.102 | K37: =(J37/J$5)*K$5 -> 42634.223
B38: Other Non-Operating Adjustments | G38: =G67-SUM(G31,G32:G37) -> -33498.147 | H38: =H67-SUM(H31,H32:H37) -> -49406.873 | I38: =I67-SUM(I31,I32:I37) -> -65382.562 | J38: =J67-SUM(J31,J32:J37) -> -81425.881 | K38: =K67-SUM(K31,K32:K37) -> -97537.509
B39: Total Long-term Assets | D39: -2756 | E39: -1289 | F39: 2516 | G39: =SUM(G32:G37) -> 448161.51 | H39: =SUM(H32:H37) -> 449683.4 | I39: =SUM(I32:I37) -> 451220.52 | J39: =SUM(J32:J37) -> 452773 | K39: =SUM(K32:K37) -> 454341.01
B40: Total Assets | D40: 411976 | E40: 512163 | F40: 619003 | G40: =SUM(G31,G39,G38) -> 613394.55 | H40: =SUM(H31,H39,H38) -> 616523.34 | I40: =SUM(I31,I39,I38) -> 628556.84 | J40: =SUM(J31,J39,J38) -> 649665.41 | K40: =SUM(K31,K39,K38) -> 680022.27
B42: Accounts Payable | D42: 18095 | E42: 21996 | F42: 27724 | G42: =(F42/F$5)*G$5 -> 28001.24 | H42: =(G42/G$5)*H$5 -> 28281.252 | I42: =(H42/H$5)*I$5 -> 28564.065 | J42: =(I42/I$5)*J$5 -> 28849.706 | K42: =(J42/J$5)*K$5 -> 29138.203 | ZZ42: BS_ACCOUNTS_PAYABLE
B43: Other Payables | D43: 4152 | E43: 5017 | F43: 7211 | G43: =(F43/F$5)*G$5 -> 7283.11 | H43: =(G43/G$5)*H$5 -> 7355.9411 | I43: =(H43/H$5)*I$5 -> 7429.5005 | J43: =(I43/I$5)*J$5 -> 7503.7955 | K43: =(J43/J$5)*K$5 -> 7578.8335
B44: Accrued Expenses | D44: 0 | E44: 0 | F44: 0 | G44: =(F44/F$5)*G$5 -> 0 | H44: =(G44/G$5)*H$5 -> 0 | I44: =(H44/H$5)*I$5 -> 0 | J44: =(I44/I$5)*J$5 -> 0 | K44: =(J44/J$5)*K$5 -> 0 | ZZ44: BS_ACCRUED_LIABILITIES
...

Sheet RV
B2: Microsoft Corporation Relative Valuation
D4: EV/Sales | E4: Price/Sales | F4: Price/Earnings | G4: Price/Book Value | I4: Weight
B5: Microsoft Corporation | D5: =G16/F16 -> 12.71215 | E5: =E16/(F16/(K16/1000000)) -> 12.658682 | F5: =E16/I16 -> 35.024194 | G5: =E16/(J16/(K16/1000000)) -> 10.382744 | I5: EV/Sales | J5: 0.25
B6: GM | D6: =G17/F17 -> 0.96295019 | E6: =E17/(F17/(K17/1000000)) -> 0.44987255 | F6: =E17/I17 -> 11.725275 | G6: =E17/(J17/(K17/1000000)) -> 1.3369643 | I6: Price/Sales | J6: 0.25
B7: ORCL | D7: =G18/F18 -> 11.778322 | E7: =E18/(F18/(K18/1000000)) -> 10.372205 | F7: =E18/I18 -> 47.864055 | G7: =E18/(J18/(K18/1000000)) -> 29.11125 | I7: Price/Earnings | J7: 0.25
B8: TSLA | D8: =G19/F19 -> 14.700758 | E8: =E19/(F19/(K19/1000000)) -> 15.996484 | F8: =E19/I19 -> 218.9902 | G8: =E19/(J19/(K19/1000000)) -> 21.432344 | I8: Price/Book Value | J8: 0.25
B9: AAPL | D9: =G20/F20 -> 10.239844 | E9: =E20/(F20/(K20/1000000)) -> 10.245037 | F9: =E20/I20 -> 38.089812 | G9: =E20/(J20/(K20/1000000)) -> 57.824646
B10: Low | D10: =MIN(D5:D9) -> 0.96295019 | E10: =MIN(E5:E9) -> 0.44987255 | F10: =MIN(F5:F9) -> 11.725275 | G10: =MIN(G5:G9) -> 1.3369643 | I10: Implied Price Target | J10: =(D13*J5)+(E13*J6)+(F13*J7)+(G13*J8) -> 704.02863
B11: Average | D11: =AVERAGE(D5:D9) -> 10.078805 | E11: =AVERAGE(E5:E9) -> 9.9444559 | F11: =AVERAGE(F5:F9) -> 70.338706 | G11: =AVERAGE(G5:G9) -> 24.01759 | I11: Implied Upside/Downside | J11: =(J10/E16)-1 -> 0.47369566
B12: High | D12: =MAX(D5:D9) -> 14.700758 | E12: =MAX(E5:E9) -> 15.996484 | F12: =MAX(F5:F9) -> 218.9902 | G12: =MAX(G5:G9) -> 57.824646
B13: Microsoft Corporation | D13: =(((D11)*F16)-H16)/(K16/1000000) -> 376.30211 | E13: =E11*(F16/(K16/1000000)) -> 375.29697 | F13: =F11*(I16) -> 959.41996 | G13: =G11*(J16/(K16/1000000)) -> 1105.0955
B15: Financials | D15: Market Cap | E15: Share Price | F15: Sales | G15: Enterprise Value | H15: Net Debt | I15: EPS | J15: Book Value | K15: Shares/OS
B16: Microsoft Corporation | D16: 3550971.8 | E16: 477.73 | F16: 281724 | G16: 3581317.8 | H16: 30346 | I16: 13.64 | J16: 343479 | K16: 7465000000
B17: GM | D17: 69676.309 | E17: 74.69 | F17: 187442 | G17: 180497.31 | H17: 110821 | I17: 6.37 | J17: 63072 | K17: 1129000000
B18: ORCL | D18: 582745.93 | E18: 207.73 | F18: 57399 | G18: 676063.93 | H18: 93318 | I18: 4.34 | J18: 20451 | K18: 2866000000
B19: TSLA | D19: 1438633.1 | E19: 446.74 | F19: 97690 | G19: 1436117.1 | H19: -2516 | I19: 2.04 | J19: 72913 | K19: 3498000000
B20: AAPL | D20: 4198700.7 | E20: 284.15 | F20: 416161 | G20: 4261423.7 | H20: 62723 | I20: 7.46 | J20: 73733 | K20: 15004697000

Sheet Beta
B2: Ticker | C2: MSFT
B3: Benchmark | C3: S&P 500
B4: Lookback (years) | C4: 5
B5: Beta | C5: =SLOPE(E8:E1260,F8:F1260) -> 1.1566004
B6: Date | C6: Ticker Adj Close | D6: Benchmark Adj Close | E6: Ticker Returns | F6: Benchmark Returns
B7: 44172 | C7: 205.61977 | D7: 3691.96
B8: 44173 | C8: 207.27016 | D8: 3702.25 | E8: =((C8/C7)-1)*100 -> 0.80264201 | F8: =((D8/D7)-1)*100 -> 0.27871481
B9: 44174 | C9: 203.23055 | D9: 3672.8201 | E9: =((C9/C8)-1)*100 -> -1.9489597 | F9: =((D9/D8)-1)*100 -> -0.79492016
B10: 44175 | C10: 202.0023 | D10: 3668.1001 | E10: =((C10/C9)-1)*100 -> -0.60435845 | F10: =((D10/D9)-1)*100 -> -0.12851081
B11: 44176 | C11: 204.63148 | D11: 3663.46 | E11: =((C11/C10)-1)*100 -> 1.3015599 | F11: =((D11/D10)-1)*100 -> -0.12649973
B12: 44179 | C12: 205.53343 | D12: 3647.49 | E12: =((C12/C11)-1)*100 -> 0.44076649 | F12: =((D12/D11)-1)*100 -> -0.4359259
B13: 44180 | C13: 205.46623 | D13: 3694.6201 | E13: =((C13/C12)-1)*100 -> -0.032695268 | F13: =((D13/D12)-1)*100 -> 1.2921249
B14: 44181 | C14: 210.40791 | D14: 3701.1699 | E14: =((C14/C13)-1)*100 -> 2.4051061 | F14: =((D14/D13)-1)*100 -> 0.17727952
B15: 44182 | C15: 210.54224 | D15: 3722.48 | E15: =((C15/C14)-1)*100 -> 0.063839386 | F15: =((D15/D14)-1)*100 -> 0.57576548
B16: 44183 | C16: 209.74579 | D16: 3709.4099 | E16: =((C16/C15)-1)*100 -> -0.37828408 | F16: =((D16/D15)-1)*100 -> -0.35111185
B17: 44186 | C17: 213.58394 | D17: 3694.9199 | E17: =((C17/C16)-1)*100 -> 1.8299056 | F17: =((D17/D16)-1)*100 -> -0.39062791
B18: 44187 | C18: 214.8793 | D18: 3687.26 | E18: =((C18/C17)-1)*100 -> 0.6064896 | F18: =((D18/D17)-1)*100 -> -0.20730929
B19: 44188 | C19: 212.0775 | D19: 3690.01 | E19: =((C19/C18)-1)*100 -> -1.3038964 | F19: =((D19/D18)-1)*100 -> 0.074581125
... B1260: 45994 | C1260: 477.73001 | D1260: 6849.7202 | E1260: =((C1260/C1259)-1)*100 -> -2.5040794 | F1260: =((D1260/D1259)-1)*100 -> 0.29797913

Sheet DCF Q
B2: "Company Name" DCF Analysis (UNITS)
B4: WACC | G4: Other Assumptions
B5: Beta | E5: # | G5: Fiscal Year End | J5: 46022
B6: Market Risk Premium | E6: # | G6: LTGR | J6: 0.02
B7: Risk Free Rate | E7: # | G7: Cash & Equivalents | J7: # | L7: 1 year (4 Quarters) historical and forecasted
B8: Cost of Equity | E8: =E7+(E5*E6) -> #VALUE! | G8: Diluted S/O | J8: #
B9: Weight of Equity | E9: =J10/SUM(J10:J11) -> #VALUE! | G9: Current Price | J9: #
B10: Cost of Debt | E10: # | G10: Mkt Cap | J10: =J8*J9 -> #VALUE!
B11: After Tax CoD | E11: =E10*(1-E13) -> #VALUE! | G11: BV debt
B12: Weight of Debt | E12: =1-E9 -> #VALUE! | G12: Financial Units
B13: Tax Rate | E13: #
B14: WACC | E14: =(E9*E8)+(E11*E12) -> #VALUE!
B16: Free Cash Flow | D16: Q1 "YEAR""A" | E16: Q2 "YEAR""A" | F16: Q3 "YEAR""A" | G16: Q4 "YEAR""A" | H16: "####"A | I16: Q1 "YEAR""E" | J16: Q2 "YEAR""E" | K16: Q3 "YEAR""E" | L16: Q4 "YEAR""E" | M16: "####"E
B17: Revenue | D17: HIST | E17: HIST | F17: HIST | G17: HIST | H17: =SUM(D17:G17) -> 0 | I17: Forecast Formula | J17: Forecast Formula | K17: Forecast Formula | L17: Forecast Formula | M17: =SUM(I17:L17) -> 0
B18: Revenue Growth (%) | E18: =IFERROR(E17/D17-1,"") | F18: =IFERROR(F17/E17-1,"") | G18: =IFERROR(G17/F17-1,"") | I18: =I17/H17-1 -> #VALUE! | J18: =J17/I17-1 -> #VALUE! | K18: =K17/J17-1 -> #VALUE! | L18: =L17/K17-1 -> #VALUE!
B19: (-) COGS | D19: HIST | E19: HIST | F19: HIST | G19: HIST | H19: =SUM(D19:G19) -> 0 | M19: =SUM(I19:L19) -> 0
B20: GP | D20: =D17+D19 -> #VALUE! | E20: =E17+E19 -> #VALUE! | F20: =F17+F19 -> #VALUE! | G20: =G17+G19 -> #VALUE! | H20: =H17+H19 -> 0 | I20: =I17+I19 -> #VALUE! | J20: =J17+J19 -> #VALUE! | K20: =K17+K19 -> #VALUE! | ... M20: =M17+M19 -> 0
B21: GP Margin (%) | D21: =D19/D17 -> #VALUE! | E21: =E19/E17 -> #VALUE! | F21: =F19/F17 -> #VALUE! | G21: =G19/G17 -> #VALUE! | H21: =H19/H17 -> #DIV/0! | I21: =I19/I17 -> #VALUE! | J21: =J19/J17 -> #VALUE! | K21: =K19/K17 -> #VALUE! | ... M21: =M19/M17 -> #DIV/0!
B23: (-) Op Ex | D23: HIST | E23: HIST | F23: HIST | G23: HIST | H23: =SUM(D23:G23) -> 0 | I23: Forecast Formula | J23: Forecast Formula | K23: Forecast Formula | L23: Forecast Formula | M23: =SUM(I23:L23) -> 0
B24: EBIT | D24: =D20+D23 -> #VALUE! | E24: =E20+E23 -> #VALUE! | F24: =F20+F23 -> #VALUE! | G24: =G20+G23 -> #VALUE! | H24: =H20+H23 -> 0 | I24: =I20+I23 -> #VALUE! | J24: =J20+J23 -> #VALUE! | K24: =K20+K23 -> #VALUE! | ... M24: =M20+M23 -> 0
B25: EBIT Margin (%) | D25: =D24/D17 -> #VALUE! | E25: =E24/E17 -> #VALUE! | F25: =F24/F17 -> #VALUE! | G25: =G24/G17 -> #VALUE! | H25: =H23/H17 -> #DIV/0! | I25: =I23/I17 -> #VALUE! | J25: =J23/J17 -> #VALUE! | K25: =K23/K17 -> #VALUE! | L25: =L23/L17 -> #VALUE! | M25: =M23/M17 -> #DIV/0!
B27: NOPAT | D27: =D24*(1-$E$13) -> #VALUE! | E27: =E24*(1-$E$13) -> #VALUE! | F27: =F24*(1-$E$13) -> #VALUE! | G27: =G24*(1-$E$13) -> #VALUE! | H27: =H24*(1-$E$13) -> #VALUE! | I27: =I24*(1-$E$13) -> #VALUE! | J27: =J24*(1-$E$13) -> #VALUE! | K27: =K24*(1-$E$13) -> #VALUE! | ... M27: =M24*(1-$E$13) -> #VALUE!
B28: (+) D&A | D28: HIST | E28: HIST | F28: HIST | G28: HIST | H28: =SUM(D28:G28) -> 0 | I28: Forecast Formula | J28: Forecast Formula | K28: Forecast Formula | L28: Forecast Formula | M28: =SUM(I28:L28) -> 0
B29: (-) CapEx | D29: HIST | E29: HIST | F29: HIST | G29: HIST | H29: =SUM(D29:G29) -> 0 | I29: Forecast Formula | J29: Forecast Formula | K29: Forecast Formula | L29: Forecast Formula | M29: =SUM(I29:L29) -> 0
B30: (-) Changes in WC | D30: HIST | E30: HIST | F30: HIST | G30: HIST | H30: =SUM(D30:G30) -> 0 | I30: Forecast Formula | J30: Forecast Formula | K30: Forecast Formula | L30: Forecast Formula | M30: =SUM(I30:L30) -> 0
B31: Unlevered Free Cash Flow | D31: =D27+D28+D29+D30 -> #VALUE! | E31: =E27+E28+E29+E30 -> #VALUE! | F31: =F27+F28+F29+F30 -> #VALUE! | G31: =G27+G28+G29+G30 -> #VALUE! | H31: =H27+H28+H29+H30 -> #VALUE! | I31: =I27+I28+I29+I30 -> #VALUE! | J31: =J27+J28+J29+J30 -> #VALUE! | K31: =K27+K28+K29+K30 -> #VALUE! | ... M31: =M27+M28+M29+M30 -> #VALUE!
B33: DCF | I33: Year"E" | J33: Year"E" | K33: Year"E" | L33: Year"E" | M33: Year"E"
B34: Discount Period | I34: =YEARFRAC(TODAY(),$J$5) -> 0.075 | J34: =I34+0.25 -> 0.325 | K34: =J34+0.25 -> 0.575 | L34: =K34+0.25 -> 0.825
B35: Discount Factor | I35: =(1/(1+$E$14))^I34 -> #VALUE! | J35: =(1/(1+$E$14))^J34 -> #VALUE! | K35: =(1/(1+$E$14))^K34 -> #VALUE! | L35: =(1/(1+$E$14))^L34 -> #VALUE!
B37: PV of UFCF | I37: =I31*I35 -> #VALUE! | J37: =J31*J35 -> #VALUE! | K37: =K31*K35 -> #VALUE! | L37: =L31*L35 -> #VALUE! | M37: =SUM(I37:L37) -> #VALUE!
B38: Total PV of UFCF | M38: =SUM(M37) -> #VALUE!
B40: Terminal Value | M40: =(M31*(1+J6))/(E14-F2) -> #VALUE!
B41: PV of TV | M41: =M40*M35 -> #VALUE!
B43: Enterprise Value | M43: =M38+M41 -> #VALUE!
B44: (-) Net Debt | M44: =-($J$11-$J$7) -> #VALUE!
B45: Equity Value | M45: =M43+M44 -> #VALUE!
B47: (/) Shares Outstanding | M47: =J8 -> #
B48: Per Share Price Target | M48: =M45/M47 -> #VALUE!
B49: Implied Upside/Downside | M49: =M48/J9-1 -> #VALUE!

Sheet 3-STMT Q
B2: "Company Name" 3 Statement Model (UNITS)
B4: Income Statement
D5: Q1 "YEAR""A" | E5: Q2 "YEAR""A" | F5: Q3 "YEAR""A" | G5: Q4 "YEAR""A" | H5: "####"A | I5: Q1 "YEAR""E" | J5: Q2 "YEAR""E" | K5: Q3 "YEAR""E" | L5: Q4 "YEAR""E" | M5: "####"E | O5: Assumptions | P5: Type | Q5: Value
B6: Line Item | O6: Revenue | P6: Custom | Q6: 0.02 | R6: 0.04 | S6: 0.03
B7: Line Item | O7: Gross Margin | P7: Step | Q7: 0.005
B8: Gross Income | O8: Operating Costs | P8: Step | Q8: 0.0075
B9: Gross Margin % | O9: EBITDA Margin | P9: Custom | R9: **ford doesn’t report
B10: Line Item | O10: Tax Rate | P10: Constant | Q10: 0.21
B11: Line Item | O11: Interest Rate on Debt | P11: Custom | Q11: 0.06 | R11: 0.05 | S11: 0.04 | T11: 0.07
B12: Operating Income
B13: Operating Margin %
B14: Line Item
B15: Income before Taxes
B16: Income Tax Expense
B17: Net Income
B18: Net Income Margin %
B19: EPS
B21: Balance Sheet
B22: Assets | D22: Q1 "YEAR""A" | E22: Q2 "YEAR""A" | F22: Q3 "YEAR""A" | G22: Q4 "YEAR""A" | H22: "####"A | I22: Q1 "YEAR""E" | J22: Q2 "YEAR""E" | K22: Q3 "YEAR""E" | L22: Q4 "YEAR""E" | M22: "####"E
B23: Line Item
B24: Line Item
B25: Total Current Assets
B26: Line Item
B27: Line Item
B28: Line Item
B29: Line Item
B30: Total Assets
B32: Liabilties
B33: Line Item
B34: Line Item
B35: Line Item
... B51: Cash Flow Statement
B52: Cash Flows from Operating Activities | D52: Q1 "YEAR""A" | E52: Q2 "YEAR""A" | F52: Q3 "YEAR""A" | G52: Q4 "YEAR""A" | H52: "####"A | I52: Q1 "YEAR""E" | J52: Q2 "YEAR""E" | K52: Q3 "YEAR""E" | L52: Q4 "YEAR""E" | M52: "####"E
B53: Line Item
B54: Line Item
B55: Total Current Assets
B56: Line Item
B57: Line Item
B58: Line Item
B59: Line Item
...

Sheet 3-STMT Quarterly
B2: "Company Name" Balance Sheet (UNITS)
B4: Assets | D4: Q1 "YEAR""A" | E4: Q2 "YEAR""A" | F4: Q3 "YEAR""A" | G4: Q4 "YEAR""A" | H4: "####"A | I4: Q1 "YEAR""E" | J4: Q2 "YEAR""E" | K4: Q3 "YEAR""E" | L4: Q4 "YEAR""E" | M4: "####"E
B5: Line Item
B6: Line Item
B7: Total Current Assets
B8: Line Item
B9: Line Item
B10: Line Item
B11: Line Item
B12: Total Assets
B14: Liabilties
B15: Line Item
B16: Line Item
B17: Line Item
... B31: Total Liabilities and Equity

Sheet CF STMT Annual 
B2: "Company Name" Statements of Cash Flows (UNITS)
B4: Cash Flows from Operating Activities | D4: Year"A" | E4: Year"A" | F4: Year"A" | G4: Year"A" | H4: Year"A" | I4: Year"E" | J4: Year"E"
B5: Line Item
B6: Line Item
B7: Total Current Assets
B8: Line Item
B9: Line Item
B10: Line Item
B11: Line Item
B12: Net Cash Provided by/(used in) Operating Activities
B14: Cash Flows from Investing Activities
B15: Line Item
B16: Line Item
B17: Line Item
... B36: Cash, Cash Equivalents, and Restricted Cash at End of Period

Sheet CF STMT Quarterly
B2: "Company Name" Statements of Cash Flows (UNITS)
B4: Cash Flows from Operating Activities | D4: Q1 "YEAR""A" | E4: Q2 "YEAR""A" | F4: Q3 "YEAR""A" | G4: Q4 "YEAR""A" | H4: "####"A | I4: Q1 "YEAR""E" | J4: Q2 "YEAR""E" | K4: Q3 "YEAR""E" | L4: Q4 "YEAR""E" | M4: "####"E
B5: Line Item
B6: Line Item
B7: Total Current Assets
B8: Line Item
B9: Line Item
B10: Line Item
B11: Line Item
B12: Net Cash Provided by/(used in) Operating Activities
B14: Cash Flows from Investing Activities
B15: Line Item
B16: Line Item
B17: Line Item
... B36: Cash, Cash Equivalents, and Restricted Cash at End of Period
